Workbook
Name WorkType: Config!#REF!

Sheet Read-Me
B2: Instruction Manual for WBS Template
B4: This template is designed to assist project managers in estimating and tracking efforts for various project tasks. It organizes tasks by complexity and work types, providing a structured way to manage and update project efforts. The workflow covers five main sheets:
B5: 1. Estimation Details
B6: 2. Pre-Estimate Checklist
B7: 3. Effort Summary
B8: 4. Estimation WBS
B9: 5. Complexity & Effort
B10: 6. Key RAID
B11: 7.Config
B13: 1. Estimation Details Sheet
B15: Purpose: Capture all relevant project and client information to set the context for estimation and track changes.
B17: Columns to Update:
... B101: The Config sheet contains predefined fields for Domain, Practice, measurement units, Engagement Type, RAID details, Contingency %, and Productivity Adjustment factors, which are locked for general users. Users must contact the Template Administrator for any updates or changes to this non-editable sheet.

Sheet Estimation Details
B5: Estimation Details | E5: Estimation change History
B6: Project ID & Project Name (FreshSales) | C6: 90000 - DIOOOJ | E6: Estimation Date | F6: Estimation Version | G6: Document Revision History | H6: Estimated /Revised By | I6: Approved By
B7: Client ID & Name (FreshSales) | C7: 900000 - Project name | E7: 45676 | F7: 1 | G7: Initial Estimate | H7: Delivery manager / PM
B8: Date of Estimate (DD-MM-YYYY) | C8: 45841
B9: Engagement Start Date (DD-MM-YYYY)
B10: Engagement Type | C10: Fixed Price
B11: Expected Duration (Months)
B12: Domain | C12: PS&D - Public Sector & Defense
B13: Practice | C13: Databricks
B14: Project Description(Brief)
B15: Requirements Availability
B16: Requirements stability
B17: Stringent Quality Requirements
B18: Stringent Process Requirements

Sheet Pre-estimate checklist
B2: Pre-estimate checklist:
B3: Project Process | C3: Yes | D3: No | E3: Not necessary | F3: Remarks
B5: Requirements
B6: Are the Project Requirements clearly documented and Understood? (by both Exponentia and the Client?) | D6: X
B7: Is the criteria for meeting each requirement defined? | D7: X
B8: Are the Project Requirements Baselined (Under change control)? | D8: X
B9: Is there a "Client approved" plan for Requirements changes? | D9: X
B10: Has a Requirements Traceability Matrix been developed? | D10: X
B11: Have the requirements been validated against the business objectives? | D11: X
B12: Have you considered all of the processes that must be followed during the project life cycle | D12: X
B13: Have you considered all of the interfaces that must be adhered to? | D13: X
B16: Scoping
B17: Has a Statement of Work (SOW) been reviewed/approved by the Client | D17: X
B18: Has the Statement of Work been reviewed by delivery team | D18: X
B19: Has a Work Breakdown Structure (WBS) been reviewed by the Client | D19: X
B20: Has the WBS been reviewed by delivery team | D20: X
B23: Risk
B24: Has a formal Risk Assessment been done? (including probability, impacts, avoidance & recovery) | D24: X
B25: Is there an approved Risk Management Plan? | D25: X
B26: Was a Client representative involved with the Risk Management Plan? | D26: X
B27: Were appropriate delivery team resources involved in the Risk Management Plan? | D27: X
B30: Environments
B31: Is the process for identifying, acquiring, establishing, and verifying the environment understood and included in the plans for the project? | D31: X
B32: Is the Development environment adequate to support the project? | D32: X
B33: Is the Operational environment adequate to support the project? | D33: X
B36: Resources
B37: Are appropriate resources available for the project? | D37: X
B38: Are the resources committed to participate in the required activities? | D38: X
B39: Is there a training plan to cover deficiencies? | D39: X

Sheet Efforts Summary
B2: =_xlfn.CONCAT("Summary of Efforts for :- ", 'Estimation Details'!C6) -> Summary of Efforts for :- 90000 - DIOOOJ
B3: Activities | C3: Phase | D3: Effort Distribution % wrt CUT | E3: Effort Distribution % wrt Total Effort | F3: Estimated Effort (Hrs) | G3: Adjusted Efforts (Hrs) Distribution | H3: Final Effort (Hrs) | I3: Final Effort (MD) | J3: Final Effort (MW) | K3: Justification / Remark for Adjustment (It is mandatory to update this, if effort is adjusted in the column F)
B4: Business Architecture & Environment Setup | C4: L1 | D4: 0.05 | E4: =IF($F$20>0,F4/$F$20,0) -> 0 | F4: =$F$8*D4 -> 0 | H4: =IF(G4>0,G4,F4) -> 0 | I4: =H4/Config!$H$3 -> 0 | J4: =I4/Config!$H$4 -> 0
B5: Requirement Development | C5: L2 | D5: 0.2 | E5: =IF($F$20>0,F5/$F$20,0) -> 0 | F5: =$F$8*D5 -> 0 | H5: =IF(G5>0,G5,F5) -> 0 | I5: =H5/Config!$H$3 -> 0 | J5: =I5/Config!$H$4 -> 0
B6: Software Architecture and Functional Design | C6: L3 | D6: 0.2 | E6: =IF($F$20>0,F6/$F$20,0) -> 0 | F6: =$F$8*D6 -> 0 | H6: =IF(G6>0,G6,F6) -> 0 | I6: =H6/Config!$H$3 -> 0 | J6: =I6/Config!$H$4 -> 0
B7: Requirement Assessment and Detailed Design | C7: L4 | D7: 0.2 | E7: =IF($F$20>0,F7/$F$20,0) -> 0 | F7: =$F$8*D7 -> 0 | H7: =IF(G7>0,G7,F7) -> 0 | I7: =H7/Config!$H$3 -> 0 | J7: =I7/Config!$H$4 -> 0
B8: Coding and Unit Test | C8: L5 | D8: 1 | E8: =IF($F$20>0,F8/$F$20,0) -> 0 | F8: ='Estimation-WBS'!O5*D21 -> 0 | H8: =IF(G8>0,G8,F8) -> 0 | I8: =H8/Config!$H$3 -> 0 | J8: =I8/Config!$H$4 -> 0
B9: Integration Testing | C9: L6 | D9: 0.2 | E9: =IF($F$20>0,F9/$F$20,0) -> 0 | F9: =$F$8*D9 -> 0 | H9: =IF(G9>0,G9,F9) -> 0 | I9: =H9/Config!$H$3 -> 0 | J9: =I9/Config!$H$4 -> 0
B10: System Testing | C10: L7 | D10: 0.2 | E10: =IF($F$20>0,F10/$F$20,0) -> 0 | F10: =$F$8*D10 -> 0 | H10: =IF(G10>0,G10,F10) -> 0 | I10: =H10/Config!$H$3 -> 0 | J10: =I10/Config!$H$4 -> 0
B11: Document Preperations | C11: L8 | D11: 0.1 | E11: =IF($F$20>0,F11/$F$20,0) -> 0 | F11: =$F$8*D11 -> 0 | H11: =IF(G11>0,G11,F11) -> 0 | I11: =H11/Config!$H$3 -> 0 | J11: =I11/Config!$H$4 -> 0
B12: User Acceptance Test - UAT (Support) | C12: L9 | D12: 0.1 | E12: =IF($F$20>0,F12/$F$20,0) -> 0 | F12: =$F$8*D12 -> 0 | H12: =IF(G12>0,G12,F12) -> 0 | I12: =H12/Config!$H$3 -> 0 | J12: =I12/Config!$H$4 -> 0
B13: Prepare Production and Deployment | C13: L10 | D13: 0.1 | E13: =IF($F$20>0,F13/$F$20,0) -> 0 | F13: =$F$8*D13 -> 0 | H13: =IF(G13>0,G13,F13) -> 0 | I13: =H13/Config!$H$3 -> 0 | J13: =I13/Config!$H$4 -> 0
B14: Production Support - Hyper Care | C14: L11 | D14: 0.1 | E14: =IF($F$20>0,F14/$F$20,0) -> 0 | F14: =$F$8*D14 -> 0 | H14: =IF(G14>0,G14,F14) -> 0 | I14: =H14/Config!$H$3 -> 0 | J14: =I14/Config!$H$4 -> 0
B15: Any other Task/Activity | C15: L12 | E15: =IF($F$20>0,F15/$F$20,0) -> 0 | H15: =IF(G15>0,G15,F15) -> 0 | I15: =H15/Config!$H$3 -> 0 | J15: =I15/Config!$H$4 -> 0
B16: Total Efforts | D16: =SUM(D4:D15) -> 2.45 | F16: =SUM(F4:F15) -> 0 | H16: =SUM(H4:H15) -> 0 | I16: =SUM(I4:I15) -> 0 | J16: =SUM(J4:J15) -> 0
B17: Project Mgmt + Quality Mgmt | D17: 0.2 | E17: =IF($F$20>0,F17/$F$20,0) -> 0 | F17: =F16*$D$17 -> 0 | H17: =H16*$D$17 -> 0 | I17: =I16*$D$17 -> 0 | J17: =J16*$D$17 -> 0
B18: Total Efforts (Inc Project Mgmt + Quality Mgmt) | E18: =IF($F$20>0,F18/$F$20,0) -> 0 | F18: =SUM(F16:F17) -> 0 | H18: =SUM(H16:H17) -> 0 | I18: =SUM(I16:I17) -> 0 | J18: =SUM(J16:J17) -> 0
B19: Contingency% | D19: 10 | E19: =IF($F$20>0,F19/$F$20,0) -> 0 | F19: =F18*$D$19/100 -> 0 | H19: =H18*$D$19/100 -> 0 | I19: =I18*$D$19/100 -> 0 | J19: =J18*$D$19/100 -> 0
B20: Grand Total Efforts (Including Contingency) | F20: =F18+F19 -> 0 | H20: =H18+H19 -> 0 | I20: =I18+I19 -> 0 | J20: =J18+J19 -> 0
B21: Productivity Adjustment Factor | D21: 1

Sheet Estimation-WBS
B2: Work Breakdown Structure (WBS)
B3: # SEQ No | C3: Work/Package Type | D3: Category | E3: #Objects to be | H3: Category Code | I3: Base Effort (Hrs) /Object/Complexity & Category | L3: Estimated Effort (Hrs) /Object/Category | O3: Total Effort
E4: Created | F4: Modified | G4: Deleted | I4: Create | J4: Modify | K4: Delete | L4: Create | M4: Modify | N4: Delete
B5: # | D5: Total | E5: =SUM(E6:E29) -> 0 | F5: =SUM(F6:F29) -> 0 | G5: =SUM(G6:G29) -> 0 | I5: =SUM(I6:I29) -> 0 | J5: =SUM(J6:J29) -> 0 | K5: =SUM(K6:K29) -> 0 | L5: =SUM(L6:L29) -> 0 | M5: =SUM(M6:M29) -> 0 | N5: =SUM(N6:N29) -> 0 | O5: =SUM(O6:O29) -> 0
B6: 1 | H6: =C6&"|"&D6 -> | | I6: {=_xlfn.XLOOKUP(H6,'Complexity & Effort'!F:F,'Complexity & Effort'!G:I,0)} -> 0 | J6: 0 | K6: 0 | L6: =E6*I6 -> 0 | M6: =F6*J6 -> 0 | N6: =G6*K6 -> 0 | O6: =SUM(L6:N6) -> 0
B7: 2 | H7: =C7&"|"&D7 -> | | I7: {=_xlfn.XLOOKUP(H7,'Complexity & Effort'!F:F,'Complexity & Effort'!G:I,0)} -> 0 | J7: 0 | K7: 0 | L7: =E7*I7 -> 0 | M7: =F7*J7 -> 0 | N7: =G7*K7 -> 0 | O7: =SUM(L7:N7) -> 0
B8: 3 | H8: =C8&"|"&D8 -> | | I8: {=_xlfn.XLOOKUP(H8,'Complexity & Effort'!F:F,'Complexity & Effort'!G:I,0)} -> 0 | J8: 0 | K8: 0 | L8: =E8*I8 -> 0 | M8: =F8*J8 -> 0 | N8: =G8*K8 -> 0 | O8: =SUM(L8:N8) -> 0
B9: 4 | H9: =C9&"|"&D9 -> | | I9: {=_xlfn.XLOOKUP(H9,'Complexity & Effort'!F:F,'Complexity & Effort'!G:I,0)} -> 0 | J9: 0 | K9: 0 | L9: =E9*I9 -> 0 | M9: =F9*J9 -> 0 | N9: =G9*K9 -> 0 | O9: =SUM(L9:N9) -> 0
B10: 5 | H10: =C10&"|"&D10 -> | | I10: {=_xlfn.XLOOKUP(H10,'Complexity & Effort'!F:F,'Complexity & Effort'!G:I,0)} -> 0 | J10: 0 | K10: 0 | L10: =E10*I10 -> 0 | M10: =F10*J10 -> 0 | N10: =G10*K10 -> 0 | O10: =SUM(L10:N10) -> 0
B11: 6 | H11: =C11&"|"&D11 -> | | I11: {=_xlfn.XLOOKUP(H11,'Complexity & Effort'!F:F,'Complexity & Effort'!G:I,0)} -> 0 | J11: 0 | K11: 0 | L11: =E11*I11 -> 0 | M11: =F11*J11 -> 0 | N11: =G11*K11 -> 0 | O11: =SUM(L11:N11) -> 0
B12: 7 | H12: =C12&"|"&D12 -> | | I12: {=_xlfn.XLOOKUP(H12,'Complexity & Effort'!F:F,'Complexity & Effort'!G:I,0)} -> 0 | J12: 0 | K12: 0 | L12: =E12*I12 -> 0 | M12: =F12*J12 -> 0 | N12: =G12*K12 -> 0 | O12: =SUM(L12:N12) -> 0
B13: 8 | H13: =C13&"|"&D13 -> | | I13: {=_xlfn.XLOOKUP(H13,'Complexity & Effort'!F:F,'Complexity & Effort'!G:I,0)} -> 0 | J13: 0 | K13: 0 | L13: =E13*I13 -> 0 | M13: =F13*J13 -> 0 | N13: =G13*K13 -> 0 | O13: =SUM(L13:N13) -> 0
B14: 9 | H14: =C14&"|"&D14 -> | | I14: {=_xlfn.XLOOKUP(H14,'Complexity & Effort'!F:F,'Complexity & Effort'!G:I,0)} -> 0 | J14: 0 | K14: 0 | L14: =E14*I14 -> 0 | M14: =F14*J14 -> 0 | N14: =G14*K14 -> 0 | O14: =SUM(L14:N14) -> 0
B15: 10 | H15: =C15&"|"&D15 -> | | I15: {=_xlfn.XLOOKUP(H15,'Complexity & Effort'!F:F,'Complexity & Effort'!G:I,0)} -> 0 | J15: 0 | K15: 0 | L15: =E15*I15 -> 0 | M15: =F15*J15 -> 0 | N15: =G15*K15 -> 0 | O15: =SUM(L15:N15) -> 0
B16: 12 | H16: =C16&"|"&D16 -> | | I16: {=_xlfn.XLOOKUP(H16,'Complexity & Effort'!F:F,'Complexity & Effort'!G:I,0)} -> 0 | J16: 0 | K16: 0 | L16: =E16*I16 -> 0 | M16: =F16*J16 -> 0 | N16: =G16*K16 -> 0 | O16: =SUM(L16:N16) -> 0
B17: 13 | H17: =C17&"|"&D17 -> | | I17: {=_xlfn.XLOOKUP(H17,'Complexity & Effort'!F:F,'Complexity & Effort'!G:I,0)} -> 0 | J17: 0 | K17: 0 | L17: =E17*I17 -> 0 | M17: =F17*J17 -> 0 | N17: =G17*K17 -> 0 | O17: =SUM(L17:N17) -> 0
... B29: 25 | H29: =C29&"|"&D29 -> | | I29: {=_xlfn.XLOOKUP(H29,'Complexity & Effort'!F:F,'Complexity & Effort'!G:I,0)} -> 0 | J29: 0 | K29: 0 | L29: =E29*I29 -> 0 | M29: =F29*J29 -> 0 | N29: =G29*K29 -> 0 | O29: =SUM(L29:N29) -> 0

Sheet Complexity & Effort
B2: Work Type | C2: Definition | D2: Complexity / Criterion | E2: Category | F2: Category Code | G2: Create | H2: Modify | I2: Delete
B3: Database | C3: A database is container that hold relational tables and other database structures that store and process data/metadata. Each database has its own properties such as Permanent Space, Spool Space, Temp Space, Access rights, Security details | D3: Database creation with simple configurations | E3: Simple | F3: =B3&"|"&E3 -> Database|Simple | G3: 2 | H3: 1 | I3: 0.5
B4: Database | D4: a database with a moderate size and data volume with basic transactional application support | E4: Medium | F4: =B4&"|"&E4 -> Database|Medium | G4: 4 | H4: 2 | I4: 0.5
B5: Database | D5: Database creation with advanced data types, intricate partitioning options, complex performance tuning mechanisms, robust security configurations | E5: Complex | F5: =B5&"|"&E5 -> Database|Complex | G5: 4 | H5: 2 | I5: 0.5
B6: Database | D6: Database creation with advanced data types, intricate partitioning options, complex performance tuning mechanisms, robust security configurations, Multitenant architecture, Replication etc | E6: Very Complex | F6: =B6&"|"&E6 -> Database|Very Complex | G6: 6 | H6: 3 | I6: 0.5
B7: Database Stored Procedures | C7: A stored procedure is a set of structured query language statement with an assigned name that is stored in the database in compiled form so that it can be shared by a number of programs | D7: Procedure involving single target / source Simple Calculation / aggregation | E7: Simple | F7: =B7&"|"&E7 -> Database Stored Procedures|Simple | G7: 4 | H7: 2 | I7: 0.5
B8: Database Stored Procedures | D8: Procedure involving 2-5 target / source medium Calculation / aggregation | E8: Medium | F8: =B8&"|"&E8 -> Database Stored Procedures|Medium | G8: 8 | H8: 4 | I8: 0.5
B9: Database Stored Procedures | D9: Procedure involving >5 target / source Complex Calculation / aggregation and KPI | E9: Complex | F9: =B9&"|"&E9 -> Database Stored Procedures|Complex | G9: 16 | H9: 8 | I9: 0.5
B10: Database Stored Procedures | D10: High-performance stored procedures with complex logic, recursive queries, and integration with other services. | E10: Very Complex | F10: =B10&"|"&E10 -> Database Stored Procedures|Very Complex | G10: 32 | H10: 16 | I10: 0.5
B11: Database Tables | C11: A Table is set of data element (values) using a model of vertical columns (identifiable by name) and horizontal rows, the cell being the Unit where a Row and Col intersect. A table has specified number of COL but can have any number of ROWS | D11: <= 15 columns - No constraints - No triggers - Standard data types (e.g., INT, VARCHAR) | E11: Simple | F11: =B11&"|"&E11 -> Database Tables|Simple | G11: 2 | H11: 1 | I11: 0.5
B12: Database Tables | D12: <= 30 columns - Basic constraints (e.g., PRIMARY KEY, UNIQUE) - <= 2 triggers - Foreign keys (<= 5) | E12: Medium | F12: =B12&"|"&E12 -> Database Tables|Medium | G12: 4 | H12: 2 | I12: 0.5
B13: Database Tables | D13: > 35 columns - Multiple constraints (PRIMARY KEY, UNIQUE, CHECK) - Multiple triggers (<= 5) - Foreign keys (> 5) | E13: Complex | F13: =B13&"|"&E13 -> Database Tables|Complex | G13: 8 | H13: 4 | I13: 0.5
B14: Database Tables | D14: > 50 columns - Advanced constraints and indexing - Multiple triggers (>= 5) - Partitioning - Complex foreign key relationships | E14: Very Complex | F14: =B14&"|"&E14 -> Database Tables|Very Complex | G14: 16 | H14: 8 | I14: 0.5
B15: Data mart | C15: Data mart is a subset of the data warehouse that is usually oriented to a specific business line or team. Data mart are small slices of the data warehouse. whereas Data warehouse have a enterprise wide depth, the information in data data mart pertain to single departments | D15: <=3 Fact Tables <= 10 unique KPI Measures No extensive physical design expected ( e.g. Partitioning / Indexing) | E15: Simple | F15: =B15&"|"&E15 -> Data mart|Simple | G15: 16 | H15: 8 | I15: 0.5
B16: Data mart | D16: <=10 Fact Tables <= 40 Unique KPI Measures No extensive physical design expected ( e.g. Partitioning / Indexing) | E16: Medium | F16: =B16&"|"&E16 -> Data mart|Medium | G16: 32 | H16: 16 | I16: 0.5
B17: Data mart | D17: >10 Fact Tables > 40 unique KPI Measures Extensive physical design expected ( e.g. Partitioning / Indexing) Advanced data marts with complex transformations, data quality checks, and multiple source integrations. | E17: Complex | F17: =B17&"|"&E17 -> Data mart|Complex | G17: 64 | H17: 32 | I17: 0.5
B18: Data mart | D18: >10 Fact Tables > 40 unique KPI Measures Extensive physical design expected ( e.g. Partitioning / Indexing) Large-scale, enterprise-level data marts with real-time data integration, dynamic updates, and heavy data transformations. | E18: Very Complex | F18: =B18&"|"&E18 -> Data mart|Very Complex | G18: 128 | H18: 64 | I18: 0.5
B19: Extract Transform Load-ETL | C19: ETL ( Extract, Transform, Load) is a process in data warehousing responsible for pulling data out of the source system and placing into target | D19: Includes components for data upload or retrieval, with minimum data processing logic - Simple SQL (source / target) - 0 to 2 lookups / easy validation - 0 to 3 transformation / calculations - minimal control flow logics ( if-the, case, decision tree etc) | E19: Simple | F19: =B19&"|"&E19 -> Extract Transform Load-ETL|Simple | G19: 8 | H19: 4 | I19: 0.5
B20: Extract Transform Load-ETL | D20: Includes components for moderate data processing logic - A few SQL of Moderate complexity ( e.g. simple join/union (source / target) - Up to 2 lookups / validation - 4 to 6 transformation / calculations of moderate complexity - come control flow logic and / or (configurations) parameters involved | E20: Medium | F20: =B20&"|"&E20 -> Extract Transform Load-ETL|Medium | G20: 16 | H20: 8 | I20: 0.5
B21: Extract Transform Load-ETL | D21: Includes extensive data processing logic with Numerous complex transformations - Multiple SQL with join/union / filtering / aggregations (source / target) - 2 to 5 lookups / validation - 6 to 10 transformation / calculations, use of external subroutines - parallel / segmented processing of the data stream | E21: Complex | F21: =B21&"|"&E21 -> Extract Transform Load-ETL|Complex | G21: 32 | H21: 16 | I21: 0.5
B22: Extract Transform Load-ETL | D22: Real-time integration Complex transformations (e.g., aggregations, multi-step filters) Extensive error handling and logging High-volume dataset (> 10M rows) | E22: Very Complex | F22: =B22&"|"&E22 -> Extract Transform Load-ETL|Very Complex | G22: 64 | H22: 32 | I22: 0.5
B23: Power Exchange (CDC) | C23: Change Data Capture (CDC) records for insert. update and delete activity that is applied to a database table. This makes the details of the the changes available in an easily consumed relational format. | D23: Change Data Capture (CDC) for tables < 35 COL | E23: Simple | F23: =B23&"|"&E23 -> Power Exchange (CDC)|Simple | G23: 8 | H23: 4 | I23: 0.5
B24: Power Exchange (CDC) | D24: Change Data Capture (CDC) for tables > 35 COL and < 100 COLs | E24: Medium | F24: =B24&"|"&E24 -> Power Exchange (CDC)|Medium | G24: 16 | H24: 8 | I24: 0.5
B25: Power Exchange (CDC) | D25: Change Data Capture (CDC) for tables > 100 COL and < 150 COLs | E25: Complex | F25: =B25&"|"&E25 -> Power Exchange (CDC)|Complex | G25: 32 | H25: 16 | I25: 0.5
B26: Power Exchange (CDC) | D26: Change Data Capture (CDC) for tables > 150 COL | E26: Very Complex | F26: =B26&"|"&E26 -> Power Exchange (CDC)|Very Complex | G26: 64 | H26: 32 | I26: 0.5
B27: Unix Shell Scripts | C27: A Unix shell script is a text file containing a group of commands that could be manually executed one by one at the Unix operating system command prompt | D27: Scripts having <=2 commands for file/directory/folder management | E27: Simple | F27: =B27&"|"&E27 -> Unix Shell Scripts|Simple | G27: 1 | H27: 1 | I27: 0.5
B28: Unix Shell Scripts | D28: FTP Scripts, File Movements | E28: Medium | F28: =B28&"|"&E28 -> Unix Shell Scripts|Medium | G28: 2 | H28: 2 | I28: 0.5
B29: Unix Shell Scripts | D29: FTP Scripts, File Movements and manipulation | E29: Complex | F29: =B29&"|"&E29 -> Unix Shell Scripts|Complex | G29: 4 | H29: 4 | I29: 0.5
B30: Unix Shell Scripts | D30: Shell scripts with file processing | E30: Very Complex | F30: =B30&"|"&E30 -> Unix Shell Scripts|Very Complex | G30: 8 | H30: 8 | I30: 0.5
B31: Configuration Objects | C31: Configuration objects refer to the customizable components or settings within a system that define how it behaves or interacts with other systems. These include business rules, workflows, user roles, access control, parameter values, system settings, and other objects that allow for customization without altering the core code of the system. | D31: Basic configuration objects with minimal logic, such as simple business rules or user roles. Typically involves static values or simple validation logic. | E31: Simple | F31: =B31&"|"&E31 -> Configuration Objects|Simple | G31: 8 | H31: 4 | I31: 0.5
B32: Configuration Objects | D32: Configuration objects with moderate complexity, involving multiple parameters, conditional logic, and basic error handling. May include some integration with other systems or datasets. | E32: Medium | F32: =B32&"|"&E32 -> Configuration Objects|Medium | G32: 16 | H32: 8 | I32: 0.5
B33: Configuration Objects | D33: Advanced configuration objects that include complex business rules, workflows, multi-step processes, and integration with external systems. Involves thorough testing and optimization for efficiency. | E33: Complex | F33: =B33&"|"&E33 -> Configuration Objects|Complex | G33: 32 | H33: 16 | I33: 0.5
B34: Configuration Objects | D34: Highly sophisticated configuration objects, often involving real-time integrations, dynamic business rules, and extensive parameterization. Can include highly customizable workflows, API integrations, and extensive testing. | E34: Very Complex | F34: =B34&"|"&E34 -> Configuration Objects|Very Complex | G34: 64 | H34: 32 | I34: 0.5
B35: Database Views | C35: Database view is a virtual table that shows a subset of a database's data in a user-friendly format. Database views are created from queries that run on one or more tables in the database. | D35: Simple views that aggregate data from one or two tables without complex transformations or filtering. Basic queries with basic joins. | E35: Simple | F35: =B35&"|"&E35 -> Database Views|Simple | G35: 4 | H35: 2 | I35: 0.5
B36: Database Views | D36: Views that involve multiple joins or more complex filters. May include aggregate functions or subqueries, but not requiring significant optimization. | E36: Medium | F36: =B36&"|"&E36 -> Database Views|Medium | G36: 8 | H36: 4 | I36: 0.5
B37: Database Views | D37: Multiple data sources, advanced filtering, joins, aggregation, and transformations. Performance optimization for large datasets or complex queries. | E37: Complex | F37: =B37&"|"&E37 -> Database Views|Complex | G37: 24 | H37: 8 | I37: 0.5
B38: Database Views | D38: Multiple data sources, real-time data aggregation, complex logic, advanced error handling, and high-performance optimization. Often requires indexing and fine-tuning for large datasets. | E38: Very Complex | F38: =B38&"|"&E38 -> Database Views|Very Complex | G38: 32 | H38: 16 | I38: 0.5
B39: Database Functions | C39: Database function is a specialized procedure within a database that performs a specific task, like a calculation or data manipulation, by accepting input parameters and returning a result as a single value or a set of data | D39: Simple functions with basic calculations, such as summing or counting values. Minimal or no error handling, designed for specific, straightforward tasks. | E39: Simple | F39: =B39&"|"&E39 -> Database Functions|Simple | G39: 8 | H39: 4 | I39: 0.5
B40: Database Functions | D40: Functions that include intermediate-level logic, such as conditional statements, data transformations, and aggregations. Some error handling and performance considerations. | E40: Medium | F40: =B40&"|"&E40 -> Database Functions|Medium | G40: 16 | H40: 8 | I40: 0.5
B41: Database Functions | D41: Complex functions that perform intricate calculations, nested logic, or multiple levels of transformations. Often involves performance optimization, scalability, and error handling for large data volumes. | E41: Complex | F41: =B41&"|"&E41 -> Database Functions|Complex | G41: 32 | H41: 16 | I41: 0.5
...

Sheet Key RAID
B2: High Level Risk, Assumptions, Issues, Dependencies - Having Impact on the Estimation
B3: #ID | C3: RAID | D3: Description | E3: Impact | F3: Remarks
C4: Risk

Sheet Config
B2: Domain | D2: Practice | F2: Day/Week/Month | G2: Measurement Unit | H2: # | J2: Engagement Type | L2: RAID | N2: Impact | P2: Contingency % | R2: Productivity Adjustment Factor
B3: FS&I - Financial Services & Insurance | D3: Databricks | F3: MD | G3: Hours | H3: 9 | J3: Fixed Price | L3: Risk | N3: Low | P3: 10 | R3: 1.2
B4: H&LS - Healthcare & Life Sciences | D4: MS Fabric/Power BI | F4: MW | G4: Days | H4: 5 | J4: Time & Material | L4: Assumption | N4: Medium | P4: 20 | R4: 1.1
B5: MAN - Manufacturing | D5: Qlik&Talend | F5: MM | G5: Weeks | H5: 4 | L5: Issue | N5: High | R5: 1
B6: PS&D - Public Sector & Defense | D6: Gen-AI | L6: Dependency | R6: 0.95
B7: TMT - Telecom Media & Technology | D7: Data Science | R7: 0.9
B8: R&S - Resources & Services | D8: AWS - Amazon Web Services | R8: 0.85
B9: R&E - Retail & E-Commerce | D9: Azure - Microsoft Azure | R9: 0.8
D10: GCP - Google Cloud Platform | R10: 0.75
D11: Snowflake

Sheet Template Change History
B2: Date | C2: Template Version | D2: Template Revision History | E2: Template Author/Reviser | F2: Template Approver
B3: 45676 | C3: 1 | D3: Initial Version created | E3: Laique Ahmad Shaikh / Prathibha Das | F3: Ramendra & Sudhakar
