Workbook
Name Impact: [1]Data!$D$2:$D$4
Name Importance: [1]Data!$B$2:$B$4
Name Initials: [2]Hidden!#REF!
Name Initials: [3]Hidden!#REF!
Name Initials: #REF!
Name Location: [1]Data!$E$2:$E$3
Name Names: #REF!
Name Owner: '1. Project Details'!$B$16:$B$24
Name Prioirty: [1]Data!$C$2:$C$4
Name Stage: '1. Project Details'!$C$16:$C$24
Name Stat: #REF!
Name Stats: #REF!
Name Status: '[2]1. Project Details'!#REF!
Name Status: '[3]1. Project Details'!#REF!
Name Status: [1]Data!$A$2:$A$3
Name Status: [1]Data!$A$2:$A$3
Name Status: [1]Data!$A$2:$A$3
Name Status: [1]Data!$A$2:$A$3
Name Status: [1]Data!$A$2:$A$3
Name Status: '1. Project Details'!#REF!
Name Status1: [1]Data!$A$2:$A$3
Name Team: '1. Project Details'!$H$15:$H$24
Name Team: [3]Hidden!$E$2:$E$41
Name Team: #REF!
Name Tool: '[4]SBS Forecast'!$A$41:$A$47
Name Tools: '[4]SBS Forecast'!$A$41:$A$45
Name Track: #REF!

Sheet Index
B4: INDEX
B6: Date Modified: 20-Sep-2022
C8: PROJECT DETAILS | H8: PROJECT TASK PLANNING
D10: Go to Project Details | I10: Go to Project Task Planning
C15: PROJECT MONITORING CHART | H15: RISK LOG
D17: Go to Project Monitoring | I17: Go to the Risk Log
C22: PROJECT ASSUMPTIONS | H22: ISSUE LOG
D24: Go to Assumptions | I24: Go to Issue Log
C29: PROJECT DEPENDENCIES | H29: MEETING NOTES
D31: Go to Project Dependencies | I31: Go to the Meeting Notes

Sheet Pre-Requisite
B1: Sr. no | C1: Activity Requirement | D1: Actionable by | E1: Status | F1: Remarks
B2: 1 | C2: Establish connectivity to client enviornment VDI/Laptops | H2: Note: This is generic list. Need to be updated for specific platform project
B3: 2 | C3: Ensure all the required software installed on each VDI/Laptops
B4: 3 | C4: Microsoft Azure Subscription: Obtain an active Azure subscription from the Azure portal or through an Enterprise agreement.
B5: 4 | C5: Region Selection: Choose appropriate Azure region for deploying the Azure Databricks workspace as suggested by Exponentia team/considering factors like latency and compliance requirements.
B6: 5 | C6: Azure Resource Group: Create an Azure resource group to deploy required services like Databricks, ADLS, Cosmos DB,etc. Existing resource group currently being used for synapse can also be used.
B7: 6 | C7: A contributor role is required for the user to access the Resource group.
B8: 7 | C8: A vnet is required with a public and private subnet for databricks workspace secure connectivity.
B9: 8 | C9: Required Databricks workspace account, ADLS Gen2 account and SQL/Oracle/Cosmos DB.
B10: 9 | C10: Allow Cosmos DB and Databricks workspace ports in inbound-outboud rule.
B11: 10 | C11: To integrate with Azure Synapse Analytics, ensure you have the following information: Database name, database server name, user name, and password for your Azure Synapse.
B12: 11 | C12: Required App registration and access to the Blob storage account.
B13: 12 | C13: In the Databricks portal, As per the requirement workspace access need to be provided with the appropriate user role.

Sheet  Best Practices-Proj Mngt
A1: SR | B1: Area | C1: Description | D1: Implemented Yes/No | E1: Remarks
A2: 1 | B2: Clear Project Objectives | C2: Define clear Purpose, Scope, outcome, Timeline and esnure its aligned to overall organizational goals and priorities Define specific, measurable, achievable, relevant, and time-bound (SMART) goals in the proposal Ensure all stakeholders understand the project objectives.
A3: 2 | B3: Detailed Planning | C3: Develop a comprehensive project plan that outlines tasks, timelines, resources, and Effort/budgets. Define and highlight all critical milestones like - Business Requirment Document - Technical Design - Syntem Integration Test - User Acceptance Test to ensure timely communication and approvals. Check with Sales team on Payment Milestones and ensure timely completion of activities to meet the milestones. Develop Project Plan by utilizing not more than 85% of the resource capacity. Develop plan considering resource leave plan, public Holidays etc from customer and Exponentia Develop Plan using granular WBS (Work Break Down structure). WBS should not take less than 8 hours of effort and a the same time, not more than 16 hours, assigned to one person for better progress monitoring Use project management methodologies (e.g., Agile(Scrum), Waterfall) suited to the project type. Deliver project in sprint by following Scrum ceremonies like Sprint Planning, Daily Scrum, Sprint Review(Playbacks) and Sprint retrospective and have regular Governance calls
A4: 3 | B4: Involve Stake Holders | C4: Identify all stakeholders early and involve them in the planning process. Maintain regular communication to keep stakeholders informed and engaged.
A5: 4 | B5: Risk Management | C5: Conduct a risk assessment to identify potential issues. Create a risk management plan that includes mitigation strategies for identified risks. Review Risk register on weekly basis to asses the impact and probabiity of the Risk and its impact on the Time, cost and scope of the Project Invoke Change Management if any of the above constraints (Time, cost and scope) is impacted.
A6: 5 | B6: Resource Management | C6: Allocate resources effectively, considering skills and availability. Allocate resources with clear start and end date to avoid cost over run Define clear role and responsibility and share with the team Ensure team members are adequately trained and equipped on the required technology and platform to perform their tasks.
A7: 6 | B7: Regular Monitoring and Reporting | C7: Hold regular status meetings to discuss progress, challenges, and next steps. Implement tools to track project progress and performance against the plan. Look for EWS(Early Warning Sign) and take appropriate action(s), Inform and seek help from management if needed.
A8: 7 | B8: Change Management | C8: Establish a formal change control process to manage scope changes. Assess the impact of changes on project timelines, costs, and resources before approval. Adjust and publish the revised plan.
A9: 8 | B9: Quality Assurance | C9: Define quality standards and metrics for deliverables. Develop detailed Test strategy, Test plan and Test cases Prepare Bi-Directional traceability matrix, Requirment <-> Design <->Test cases <-> Test Result Conduct regular quality checks and incorporate feedback into the development process. Conduct RCA meeting for all the finding (Change and Bug) and take corrective action
A10: 9 | B10: Effective Communication | C10: Establish clear communication channels among team members and stakeholders. Hold Weekly and Monthly governance meeting to update on the progress Use collaboration tools like MS Teams to facilitate communication and information sharing.
A11: 10 | B11: Client and User Involvement | C11: Involve clients and end-users throughout the project to gather input and feedback. Validate requirements and expectations to ensure alignment.
A12: 11 | B12: Change and Release Management | C12: Plan and execute changes and releases carefully to minimize disruption. Ensure proper testing and validation of changes before deployment.
A13: 12 | B13: Agile Practices | C13: If applicable, adopt Agile practices such as iterative development and regular feedback loops. Foster a culture of continuous improvement and adaptability.
... A15: 14 | B15: Post Project Evaluation | C15: Conduct a project or sprint retrospective to evaluate what went well and what could be improved. Gather feedback from stakeholders and team members to identify lessons learned.

Sheet Scope
B2: Scope of Work
B5: Component | C5: Project Name | D5: Target product | E5: Priority for Implementation | F5: Report Description | G5: Report Source | H5: Report Access | I5: Remarks

Sheet 1. Project Details
B2: PROJECT DETAILS | F2: Goto Index
B6: Project Name
B8: Estimated Project Start Date
B10: Estimated Project End Date
B12: Project Manager Name
B14: 1. Project Team Members, Task Groups & Stakeholders | D14: 2. Holidays / Time Off Project | G14: Governance Model | H14: Planned Leaves
B15: Name | D15: Date | E15: Holiday | H15: Team | K15: Month | L15: Start | M15: End
G16: Daily Stand-up Call
G17: Bi-Weekly Sprint Planning Meeting and Retrospective
G18: Weekly Project Review Meeting
G19: Show-n-Tell
G20: Steerco: Once a Month

Sheet Team Access & Training
A1: Access
A2: Name | B2: ID | C2: VDI | D2: Domain | E2: Password | F2: Email ID
A14: Trainings
A15: Resource Name | B15: Training(s) | C15: Start Date | D15: End Date | E15: Status | F15: Remarks

Sheet 2. Planning
B2: Project Plan | G2: Goto Index
B6: Project Task Information
B8: Project Task | C8: Sub Tasks | D8: Man Days | E8: Hours | F8: Estimated Start Date | G8: Estimated Completion Date | H8: Task Owner | I8: User/Stakeholder Involvement | J8: Remarks/Pre-requisites
B9: Project Initiation and Requirement Gathering
B10: Project Kick off
B11: Post Kick-off Activities | C11: Ensure all team members understand their tasks.
C12: Address any immediate questions or concerns.
C13: Verify that all necessary resources are in place.
C14: Client VPN Installation
C15: Arcon Installation
C16: VDI
C17: Azure and SQL Server Access
C18: SSMS installation and Access
C19: Source Server details to have connection with ADF
C20: Shared the 150 variables with transformation rules
C21: Shared the Source of Variables as well
C22: Identified Stakeholders for requirement gathering
B23: Business Requirement Document | C23: Schedule a connect with client
C24: Requirement gathering deck for Operations
C25: Requirement gathering deck for Strategy
C26: Requirement gathering deck for technology
C27: Requirement gathering deck for Risk
C28: Gather requirement of various environment
C29: BRD preparation
C30: BRD Signoff
B31: Project Planning | C31: Prepare a detailed project plan
C32: Identify the resources
C33: Task allocation
C34: Monitor the assigned activities
B35: Existing architecture assessment | C35: Understand Source data and definitions
C36: Prepare Architecture for proposed solution
C37: Review the existing transformation document
C38: Prepare the transformation document
C39: Prepare the document of data quality checks (data cleaning) to be applied for silver layer
C40: Define data storage, processing and performance optimization techniques
C41: Define logging and error handling strategies to be implemented in the solution
B42: Data Modeling | C42: Conceptual data modelling
C43: Logical data modelling
C44: Physical data modelling
C45: Physical data modelling converting Four DataMart's
...

Sheet 3. Task Monitoring
B2: Work Schedule Monitoring | O2: Return to the Index
J4: GANTT CHART LEGEND
K5: Holiday / Vacation / No Work
K6: Planned Project Work Day
K7: Task Completed
J8: COMPLETION STATUS LEGEND
K9: Task Completed Ahead of Schedule
K10: Task Completed Behind Schedule
B12: Project Task Information | J12: Week 1 | O12: Week 2 | T12: Week 3 | Y12: Week 4 | AD12: Week 5 | AI12: Week 6 | AN12: Week 7 | AS12: Week 8 | AX12: Week 9 | BC12: Week 10 | BH12: Week 11 | BM12: Week 12 | BR12: Week 13 | BW12: Week 14
B14: Project Task | C14: Estimated Start Date | D14: Estimated Completion Date | E14: Task Owner | F14: Actual Start Date | G14: Actual Completion Date | H14: Comments | I14: Status | J14: 44774 | O14: =J14+7 -> 44781 | T14: =O14+7 -> 44788 | Y14: =T14+7 -> 44795 | AD14: =Y14+7 -> 44802 | AI14: =AD14+7 -> 44809 | AN14: =AI14+7 -> 44816 | AS14: =AN14+7 -> 44823 | AX14: =AS14+7 -> 44830 | BC14: =AX14+7 -> 44837 | BH14: =BC14+7 -> 44844 | BM14: =BH14+7 -> 44851 | BR14: =BM14+7 -> 44858 | BW14: =BR14+7 -> 44865
B17: Project Kickoff | J17: =IF(#REF!="Yes","H",IF($B17="","",IF(AND($C17<=#REF!,$D17>=#REF!),IF($G17="","x","y"),""))) -> #REF! | K17: =IF(#REF!="Yes","H",IF($B17="","",IF(AND($C17<=#REF!,$D17>=#REF!),IF($G17="","x","y"),""))) -> #REF! | L17: =IF(#REF!="Yes","H",IF($B17="","",IF(AND($C17<=#REF!,$D17>=#REF!),IF($G17="","x","y"),""))) -> #REF! | M17: =IF(#REF!="Yes","H",IF($B17="","",IF(AND($C17<=#REF!,$D17>=#REF!),IF($G17="","x","y"),""))) -> #REF! | N17: =IF(#REF!="Yes","H",IF($B17="","",IF(AND($C17<=#REF!,$D17>=#REF!),IF($G17="","x","y"),""))) -> #REF! | O17: =IF(#REF!="Yes","H",IF($B17="","",IF(AND($C17<=#REF!,$D17>=#REF!),IF($G17="","x","y"),""))) -> #REF! | P17: =IF(#REF!="Yes","H",IF($B17="","",IF(AND($C17<=#REF!,$D17>=#REF!),IF($G17="","x","y"),""))) -> #REF! | Q17: =IF(#REF!="Yes","H",IF($B17="","",IF(AND($C17<=#REF!,$D17>=#REF!),IF($G17="","x","y"),""))) -> #REF! | ... CA17: =IF(#REF!="Yes","H",IF($B17="","",IF(AND($C17<=#REF!,$D17>=#REF!),IF($G17="","x","y"),""))) -> #REF!
B18: Post Kickoff Activities
B19: Client VPN Installation | J19: =IF(#REF!="Yes","H",IF($B19="","",IF(AND($C19<=#REF!,$D19>=#REF!),IF($G19="","x","y"),""))) -> #REF! | K19: =IF(#REF!="Yes","H",IF($B19="","",IF(AND($C19<=#REF!,$D19>=#REF!),IF($G19="","x","y"),""))) -> #REF! | L19: =IF(#REF!="Yes","H",IF($B19="","",IF(AND($C19<=#REF!,$D19>=#REF!),IF($G19="","x","y"),""))) -> #REF! | M19: =IF(#REF!="Yes","H",IF($B19="","",IF(AND($C19<=#REF!,$D19>=#REF!),IF($G19="","x","y"),""))) -> #REF! | N19: =IF(#REF!="Yes","H",IF($B19="","",IF(AND($C19<=#REF!,$D19>=#REF!),IF($G19="","x","y"),""))) -> #REF! | O19: =IF(#REF!="Yes","H",IF($B19="","",IF(AND($C19<=#REF!,$D19>=#REF!),IF($G19="","x","y"),""))) -> #REF! | P19: =IF(#REF!="Yes","H",IF($B19="","",IF(AND($C19<=#REF!,$D19>=#REF!),IF($G19="","x","y"),""))) -> #REF! | Q19: =IF(#REF!="Yes","H",IF($B19="","",IF(AND($C19<=#REF!,$D19>=#REF!),IF($G19="","x","y"),""))) -> #REF! | ... CA19: =IF(#REF!="Yes","H",IF($B19="","",IF(AND($C19<=#REF!,$D19>=#REF!),IF($G19="","x","y"),""))) -> #REF!
B20: Arcon Installation | J20: =IF(#REF!="Yes","H",IF($B20="","",IF(AND($C20<=#REF!,$D20>=#REF!),IF($G20="","x","y"),""))) -> #REF! | K20: =IF(#REF!="Yes","H",IF($B20="","",IF(AND($C20<=#REF!,$D20>=#REF!),IF($G20="","x","y"),""))) -> #REF! | L20: =IF(#REF!="Yes","H",IF($B20="","",IF(AND($C20<=#REF!,$D20>=#REF!),IF($G20="","x","y"),""))) -> #REF! | M20: =IF(#REF!="Yes","H",IF($B20="","",IF(AND($C20<=#REF!,$D20>=#REF!),IF($G20="","x","y"),""))) -> #REF! | N20: =IF(#REF!="Yes","H",IF($B20="","",IF(AND($C20<=#REF!,$D20>=#REF!),IF($G20="","x","y"),""))) -> #REF! | O20: =IF(#REF!="Yes","H",IF($B20="","",IF(AND($C20<=#REF!,$D20>=#REF!),IF($G20="","x","y"),""))) -> #REF! | P20: =IF(#REF!="Yes","H",IF($B20="","",IF(AND($C20<=#REF!,$D20>=#REF!),IF($G20="","x","y"),""))) -> #REF! | Q20: =IF(#REF!="Yes","H",IF($B20="","",IF(AND($C20<=#REF!,$D20>=#REF!),IF($G20="","x","y"),""))) -> #REF! | ... CA20: =IF(#REF!="Yes","H",IF($B20="","",IF(AND($C20<=#REF!,$D20>=#REF!),IF($G20="","x","y"),""))) -> #REF!
B21: VDI | J21: =IF(#REF!="Yes","H",IF($B21="","",IF(AND($C21<=#REF!,$D21>=#REF!),IF($G21="","x","y"),""))) -> #REF! | K21: =IF(#REF!="Yes","H",IF($B21="","",IF(AND($C21<=#REF!,$D21>=#REF!),IF($G21="","x","y"),""))) -> #REF! | L21: =IF(#REF!="Yes","H",IF($B21="","",IF(AND($C21<=#REF!,$D21>=#REF!),IF($G21="","x","y"),""))) -> #REF! | M21: =IF(#REF!="Yes","H",IF($B21="","",IF(AND($C21<=#REF!,$D21>=#REF!),IF($G21="","x","y"),""))) -> #REF! | N21: =IF(#REF!="Yes","H",IF($B21="","",IF(AND($C21<=#REF!,$D21>=#REF!),IF($G21="","x","y"),""))) -> #REF! | O21: =IF(#REF!="Yes","H",IF($B21="","",IF(AND($C21<=#REF!,$D21>=#REF!),IF($G21="","x","y"),""))) -> #REF! | P21: =IF(#REF!="Yes","H",IF($B21="","",IF(AND($C21<=#REF!,$D21>=#REF!),IF($G21="","x","y"),""))) -> #REF! | Q21: =IF(#REF!="Yes","H",IF($B21="","",IF(AND($C21<=#REF!,$D21>=#REF!),IF($G21="","x","y"),""))) -> #REF! | ... CA21: =IF(#REF!="Yes","H",IF($B21="","",IF(AND($C21<=#REF!,$D21>=#REF!),IF($G21="","x","y"),""))) -> #REF!
B22: Azure and SQL Server Access | J22: =IF(#REF!="Yes","H",IF($B22="","",IF(AND($C22<=#REF!,$D22>=#REF!),IF($G22="","x","y"),""))) -> #REF! | K22: =IF(#REF!="Yes","H",IF($B22="","",IF(AND($C22<=#REF!,$D22>=#REF!),IF($G22="","x","y"),""))) -> #REF! | L22: =IF(#REF!="Yes","H",IF($B22="","",IF(AND($C22<=#REF!,$D22>=#REF!),IF($G22="","x","y"),""))) -> #REF! | M22: =IF(#REF!="Yes","H",IF($B22="","",IF(AND($C22<=#REF!,$D22>=#REF!),IF($G22="","x","y"),""))) -> #REF! | N22: =IF(#REF!="Yes","H",IF($B22="","",IF(AND($C22<=#REF!,$D22>=#REF!),IF($G22="","x","y"),""))) -> #REF! | O22: =IF(#REF!="Yes","H",IF($B22="","",IF(AND($C22<=#REF!,$D22>=#REF!),IF($G22="","x","y"),""))) -> #REF! | P22: =IF(#REF!="Yes","H",IF($B22="","",IF(AND($C22<=#REF!,$D22>=#REF!),IF($G22="","x","y"),""))) -> #REF! | Q22: =IF(#REF!="Yes","H",IF($B22="","",IF(AND($C22<=#REF!,$D22>=#REF!),IF($G22="","x","y"),""))) -> #REF! | ... CA22: =IF(#REF!="Yes","H",IF($B22="","",IF(AND($C22<=#REF!,$D22>=#REF!),IF($G22="","x","y"),""))) -> #REF!
B23: SSMS installation and Access | J23: =IF(#REF!="Yes","H",IF($B23="","",IF(AND($C23<=#REF!,$D23>=#REF!),IF($G23="","x","y"),""))) -> #REF! | K23: =IF(#REF!="Yes","H",IF($B23="","",IF(AND($C23<=#REF!,$D23>=#REF!),IF($G23="","x","y"),""))) -> #REF! | L23: =IF(#REF!="Yes","H",IF($B23="","",IF(AND($C23<=#REF!,$D23>=#REF!),IF($G23="","x","y"),""))) -> #REF! | M23: =IF(#REF!="Yes","H",IF($B23="","",IF(AND($C23<=#REF!,$D23>=#REF!),IF($G23="","x","y"),""))) -> #REF! | N23: =IF(#REF!="Yes","H",IF($B23="","",IF(AND($C23<=#REF!,$D23>=#REF!),IF($G23="","x","y"),""))) -> #REF! | O23: =IF(#REF!="Yes","H",IF($B23="","",IF(AND($C23<=#REF!,$D23>=#REF!),IF($G23="","x","y"),""))) -> #REF! | P23: =IF(#REF!="Yes","H",IF($B23="","",IF(AND($C23<=#REF!,$D23>=#REF!),IF($G23="","x","y"),""))) -> #REF! | Q23: =IF(#REF!="Yes","H",IF($B23="","",IF(AND($C23<=#REF!,$D23>=#REF!),IF($G23="","x","y"),""))) -> #REF! | ... CA23: =IF(#REF!="Yes","H",IF($B23="","",IF(AND($C23<=#REF!,$D23>=#REF!),IF($G23="","x","y"),""))) -> #REF!
B24: Access of BI layer ( Power BI )
B25: Source Server details to have connection with ADF | J25: =IF(#REF!="Yes","H",IF($B25="","",IF(AND($C25<=#REF!,$D25>=#REF!),IF($G25="","x","y"),""))) -> #REF! | K25: =IF(#REF!="Yes","H",IF($B25="","",IF(AND($C25<=#REF!,$D25>=#REF!),IF($G25="","x","y"),""))) -> #REF! | L25: =IF(#REF!="Yes","H",IF($B25="","",IF(AND($C25<=#REF!,$D25>=#REF!),IF($G25="","x","y"),""))) -> #REF! | M25: =IF(#REF!="Yes","H",IF($B25="","",IF(AND($C25<=#REF!,$D25>=#REF!),IF($G25="","x","y"),""))) -> #REF! | N25: =IF(#REF!="Yes","H",IF($B25="","",IF(AND($C25<=#REF!,$D25>=#REF!),IF($G25="","x","y"),""))) -> #REF! | O25: =IF(#REF!="Yes","H",IF($B25="","",IF(AND($C25<=#REF!,$D25>=#REF!),IF($G25="","x","y"),""))) -> #REF! | P25: =IF(#REF!="Yes","H",IF($B25="","",IF(AND($C25<=#REF!,$D25>=#REF!),IF($G25="","x","y"),""))) -> #REF! | Q25: =IF(#REF!="Yes","H",IF($B25="","",IF(AND($C25<=#REF!,$D25>=#REF!),IF($G25="","x","y"),""))) -> #REF! | ... CA25: =IF(#REF!="Yes","H",IF($B25="","",IF(AND($C25<=#REF!,$D25>=#REF!),IF($G25="","x","y"),""))) -> #REF!
B26: Access to Azue Synapse to analyse the tables of variables
B27: Shared the 150 variables with transformation rules | J27: =IF(#REF!="Yes","H",IF($B27="","",IF(AND($C27<=#REF!,$D27>=#REF!),IF($G27="","x","y"),""))) -> #REF! | K27: =IF(#REF!="Yes","H",IF($B27="","",IF(AND($C27<=#REF!,$D27>=#REF!),IF($G27="","x","y"),""))) -> #REF! | L27: =IF(#REF!="Yes","H",IF($B27="","",IF(AND($C27<=#REF!,$D27>=#REF!),IF($G27="","x","y"),""))) -> #REF! | M27: =IF(#REF!="Yes","H",IF($B27="","",IF(AND($C27<=#REF!,$D27>=#REF!),IF($G27="","x","y"),""))) -> #REF! | N27: =IF(#REF!="Yes","H",IF($B27="","",IF(AND($C27<=#REF!,$D27>=#REF!),IF($G27="","x","y"),""))) -> #REF! | O27: =IF(#REF!="Yes","H",IF($B27="","",IF(AND($C27<=#REF!,$D27>=#REF!),IF($G27="","x","y"),""))) -> #REF! | P27: =IF(#REF!="Yes","H",IF($B27="","",IF(AND($C27<=#REF!,$D27>=#REF!),IF($G27="","x","y"),""))) -> #REF! | Q27: =IF(#REF!="Yes","H",IF($B27="","",IF(AND($C27<=#REF!,$D27>=#REF!),IF($G27="","x","y"),""))) -> #REF! | ... CA27: =IF(#REF!="Yes","H",IF($B27="","",IF(AND($C27<=#REF!,$D27>=#REF!),IF($G27="","x","y"),""))) -> #REF!
B28: Analyze the Shared 150 variables with transformation rules
B29: Analyze the Report to understand the variable sources
B30: Get the queries which used for applied the transformations
B31: Prepare the transformation deck for remaining 100 variables
B32: Find the Sources of Variables as well
B33: Identified Stakeholders for requirement gathering | J33: =IF(#REF!="Yes","H",IF($B33="","",IF(AND($C33<=#REF!,$D33>=#REF!),IF($G33="","x","y"),""))) -> #REF! | K33: =IF(#REF!="Yes","H",IF($B33="","",IF(AND($C33<=#REF!,$D33>=#REF!),IF($G33="","x","y"),""))) -> #REF! | L33: =IF(#REF!="Yes","H",IF($B33="","",IF(AND($C33<=#REF!,$D33>=#REF!),IF($G33="","x","y"),""))) -> #REF! | M33: =IF(#REF!="Yes","H",IF($B33="","",IF(AND($C33<=#REF!,$D33>=#REF!),IF($G33="","x","y"),""))) -> #REF! | N33: =IF(#REF!="Yes","H",IF($B33="","",IF(AND($C33<=#REF!,$D33>=#REF!),IF($G33="","x","y"),""))) -> #REF! | O33: =IF(#REF!="Yes","H",IF($B33="","",IF(AND($C33<=#REF!,$D33>=#REF!),IF($G33="","x","y"),""))) -> #REF! | P33: =IF(#REF!="Yes","H",IF($B33="","",IF(AND($C33<=#REF!,$D33>=#REF!),IF($G33="","x","y"),""))) -> #REF! | Q33: =IF(#REF!="Yes","H",IF($B33="","",IF(AND($C33<=#REF!,$D33>=#REF!),IF($G33="","x","y"),""))) -> #REF! | ... CA33: =IF(#REF!="Yes","H",IF($B33="","",IF(AND($C33<=#REF!,$D33>=#REF!),IF($G33="","x","y"),""))) -> #REF!
B34: Requirement gathering deck for Operations | J34: =IF(#REF!="Yes","H",IF($B34="","",IF(AND($C34<=#REF!,$D34>=#REF!),IF($G34="","x","y"),""))) -> #REF! | K34: =IF(#REF!="Yes","H",IF($B34="","",IF(AND($C34<=#REF!,$D34>=#REF!),IF($G34="","x","y"),""))) -> #REF! | L34: =IF(#REF!="Yes","H",IF($B34="","",IF(AND($C34<=#REF!,$D34>=#REF!),IF($G34="","x","y"),""))) -> #REF! | M34: =IF(#REF!="Yes","H",IF($B34="","",IF(AND($C34<=#REF!,$D34>=#REF!),IF($G34="","x","y"),""))) -> #REF! | N34: =IF(#REF!="Yes","H",IF($B34="","",IF(AND($C34<=#REF!,$D34>=#REF!),IF($G34="","x","y"),""))) -> #REF! | O34: =IF(#REF!="Yes","H",IF($B34="","",IF(AND($C34<=#REF!,$D34>=#REF!),IF($G34="","x","y"),""))) -> #REF! | P34: =IF(#REF!="Yes","H",IF($B34="","",IF(AND($C34<=#REF!,$D34>=#REF!),IF($G34="","x","y"),""))) -> #REF! | Q34: =IF(#REF!="Yes","H",IF($B34="","",IF(AND($C34<=#REF!,$D34>=#REF!),IF($G34="","x","y"),""))) -> #REF! | ... CA34: =IF(#REF!="Yes","H",IF($B34="","",IF(AND($C34<=#REF!,$D34>=#REF!),IF($G34="","x","y"),""))) -> #REF!
B35: Requirement gathering deck for Strategy | J35: =IF(#REF!="Yes","H",IF($B35="","",IF(AND($C35<=#REF!,$D35>=#REF!),IF($G35="","x","y"),""))) -> #REF! | K35: =IF(#REF!="Yes","H",IF($B35="","",IF(AND($C35<=#REF!,$D35>=#REF!),IF($G35="","x","y"),""))) -> #REF! | L35: =IF(#REF!="Yes","H",IF($B35="","",IF(AND($C35<=#REF!,$D35>=#REF!),IF($G35="","x","y"),""))) -> #REF! | M35: =IF(#REF!="Yes","H",IF($B35="","",IF(AND($C35<=#REF!,$D35>=#REF!),IF($G35="","x","y"),""))) -> #REF! | N35: =IF(#REF!="Yes","H",IF($B35="","",IF(AND($C35<=#REF!,$D35>=#REF!),IF($G35="","x","y"),""))) -> #REF! | O35: =IF(#REF!="Yes","H",IF($B35="","",IF(AND($C35<=#REF!,$D35>=#REF!),IF($G35="","x","y"),""))) -> #REF! | P35: =IF(#REF!="Yes","H",IF($B35="","",IF(AND($C35<=#REF!,$D35>=#REF!),IF($G35="","x","y"),""))) -> #REF! | Q35: =IF(#REF!="Yes","H",IF($B35="","",IF(AND($C35<=#REF!,$D35>=#REF!),IF($G35="","x","y"),""))) -> #REF! | ... CA35: =IF(#REF!="Yes","H",IF($B35="","",IF(AND($C35<=#REF!,$D35>=#REF!),IF($G35="","x","y"),""))) -> #REF!
B36: Requirement gathering deck for technology | J36: =IF(#REF!="Yes","H",IF($B36="","",IF(AND($C36<=#REF!,$D36>=#REF!),IF($G36="","x","y"),""))) -> #REF! | K36: =IF(#REF!="Yes","H",IF($B36="","",IF(AND($C36<=#REF!,$D36>=#REF!),IF($G36="","x","y"),""))) -> #REF! | L36: =IF(#REF!="Yes","H",IF($B36="","",IF(AND($C36<=#REF!,$D36>=#REF!),IF($G36="","x","y"),""))) -> #REF! | M36: =IF(#REF!="Yes","H",IF($B36="","",IF(AND($C36<=#REF!,$D36>=#REF!),IF($G36="","x","y"),""))) -> #REF! | N36: =IF(#REF!="Yes","H",IF($B36="","",IF(AND($C36<=#REF!,$D36>=#REF!),IF($G36="","x","y"),""))) -> #REF! | O36: =IF(#REF!="Yes","H",IF($B36="","",IF(AND($C36<=#REF!,$D36>=#REF!),IF($G36="","x","y"),""))) -> #REF! | P36: =IF(#REF!="Yes","H",IF($B36="","",IF(AND($C36<=#REF!,$D36>=#REF!),IF($G36="","x","y"),""))) -> #REF! | Q36: =IF(#REF!="Yes","H",IF($B36="","",IF(AND($C36<=#REF!,$D36>=#REF!),IF($G36="","x","y"),""))) -> #REF! | ... CA36: =IF(#REF!="Yes","H",IF($B36="","",IF(AND($C36<=#REF!,$D36>=#REF!),IF($G36="","x","y"),""))) -> #REF!
B37: Requirement gathering deck for Risk | J37: =IF(#REF!="Yes","H",IF($B37="","",IF(AND($C37<=#REF!,$D37>=#REF!),IF($G37="","x","y"),""))) -> #REF! | K37: =IF(#REF!="Yes","H",IF($B37="","",IF(AND($C37<=#REF!,$D37>=#REF!),IF($G37="","x","y"),""))) -> #REF! | L37: =IF(#REF!="Yes","H",IF($B37="","",IF(AND($C37<=#REF!,$D37>=#REF!),IF($G37="","x","y"),""))) -> #REF! | M37: =IF(#REF!="Yes","H",IF($B37="","",IF(AND($C37<=#REF!,$D37>=#REF!),IF($G37="","x","y"),""))) -> #REF! | N37: =IF(#REF!="Yes","H",IF($B37="","",IF(AND($C37<=#REF!,$D37>=#REF!),IF($G37="","x","y"),""))) -> #REF! | O37: =IF(#REF!="Yes","H",IF($B37="","",IF(AND($C37<=#REF!,$D37>=#REF!),IF($G37="","x","y"),""))) -> #REF! | P37: =IF(#REF!="Yes","H",IF($B37="","",IF(AND($C37<=#REF!,$D37>=#REF!),IF($G37="","x","y"),""))) -> #REF! | Q37: =IF(#REF!="Yes","H",IF($B37="","",IF(AND($C37<=#REF!,$D37>=#REF!),IF($G37="","x","y"),""))) -> #REF! | ... CA37: =IF(#REF!="Yes","H",IF($B37="","",IF(AND($C37<=#REF!,$D37>=#REF!),IF($G37="","x","y"),""))) -> #REF!
B38: Data modeling for Operations | J38: =IF(#REF!="Yes","H",IF($B38="","",IF(AND($C38<=#REF!,$D38>=#REF!),IF($G38="","x","y"),""))) -> #REF! | K38: =IF(#REF!="Yes","H",IF($B38="","",IF(AND($C38<=#REF!,$D38>=#REF!),IF($G38="","x","y"),""))) -> #REF! | L38: =IF(#REF!="Yes","H",IF($B38="","",IF(AND($C38<=#REF!,$D38>=#REF!),IF($G38="","x","y"),""))) -> #REF! | M38: =IF(#REF!="Yes","H",IF($B38="","",IF(AND($C38<=#REF!,$D38>=#REF!),IF($G38="","x","y"),""))) -> #REF! | N38: =IF(#REF!="Yes","H",IF($B38="","",IF(AND($C38<=#REF!,$D38>=#REF!),IF($G38="","x","y"),""))) -> #REF! | O38: =IF(#REF!="Yes","H",IF($B38="","",IF(AND($C38<=#REF!,$D38>=#REF!),IF($G38="","x","y"),""))) -> #REF! | P38: =IF(#REF!="Yes","H",IF($B38="","",IF(AND($C38<=#REF!,$D38>=#REF!),IF($G38="","x","y"),""))) -> #REF! | Q38: =IF(#REF!="Yes","H",IF($B38="","",IF(AND($C38<=#REF!,$D38>=#REF!),IF($G38="","x","y"),""))) -> #REF! | ... CA38: =IF(#REF!="Yes","H",IF($B38="","",IF(AND($C38<=#REF!,$D38>=#REF!),IF($G38="","x","y"),""))) -> #REF!
B39: Explain the approach to the developer
B40: Prepare a mapping document from Souce to Destination
B41: Data modeling for Strategy | J41: =IF(#REF!="Yes","H",IF($B41="","",IF(AND($C41<=#REF!,$D41>=#REF!),IF($G41="","x","y"),""))) -> #REF! | K41: =IF(#REF!="Yes","H",IF($B41="","",IF(AND($C41<=#REF!,$D41>=#REF!),IF($G41="","x","y"),""))) -> #REF! | L41: =IF(#REF!="Yes","H",IF($B41="","",IF(AND($C41<=#REF!,$D41>=#REF!),IF($G41="","x","y"),""))) -> #REF! | M41: =IF(#REF!="Yes","H",IF($B41="","",IF(AND($C41<=#REF!,$D41>=#REF!),IF($G41="","x","y"),""))) -> #REF! | N41: =IF(#REF!="Yes","H",IF($B41="","",IF(AND($C41<=#REF!,$D41>=#REF!),IF($G41="","x","y"),""))) -> #REF! | O41: =IF(#REF!="Yes","H",IF($B41="","",IF(AND($C41<=#REF!,$D41>=#REF!),IF($G41="","x","y"),""))) -> #REF! | P41: =IF(#REF!="Yes","H",IF($B41="","",IF(AND($C41<=#REF!,$D41>=#REF!),IF($G41="","x","y"),""))) -> #REF! | Q41: =IF(#REF!="Yes","H",IF($B41="","",IF(AND($C41<=#REF!,$D41>=#REF!),IF($G41="","x","y"),""))) -> #REF! | ... CA41: =IF(#REF!="Yes","H",IF($B41="","",IF(AND($C41<=#REF!,$D41>=#REF!),IF($G41="","x","y"),""))) -> #REF!
B42: Explain the approach to the developer
B43: Prepare a mapping document from Souce to Destination
B44: Data modeling for technology | J44: =IF(#REF!="Yes","H",IF($B44="","",IF(AND($C44<=#REF!,$D44>=#REF!),IF($G44="","x","y"),""))) -> #REF! | K44: =IF(#REF!="Yes","H",IF($B44="","",IF(AND($C44<=#REF!,$D44>=#REF!),IF($G44="","x","y"),""))) -> #REF! | L44: =IF(#REF!="Yes","H",IF($B44="","",IF(AND($C44<=#REF!,$D44>=#REF!),IF($G44="","x","y"),""))) -> #REF! | M44: =IF(#REF!="Yes","H",IF($B44="","",IF(AND($C44<=#REF!,$D44>=#REF!),IF($G44="","x","y"),""))) -> #REF! | N44: =IF(#REF!="Yes","H",IF($B44="","",IF(AND($C44<=#REF!,$D44>=#REF!),IF($G44="","x","y"),""))) -> #REF! | O44: =IF(#REF!="Yes","H",IF($B44="","",IF(AND($C44<=#REF!,$D44>=#REF!),IF($G44="","x","y"),""))) -> #REF! | P44: =IF(#REF!="Yes","H",IF($B44="","",IF(AND($C44<=#REF!,$D44>=#REF!),IF($G44="","x","y"),""))) -> #REF! | Q44: =IF(#REF!="Yes","H",IF($B44="","",IF(AND($C44<=#REF!,$D44>=#REF!),IF($G44="","x","y"),""))) -> #REF! | ... CA44: =IF(#REF!="Yes","H",IF($B44="","",IF(AND($C44<=#REF!,$D44>=#REF!),IF($G44="","x","y"),""))) -> #REF!
B45: Explain the approach to the developer
B46: Prepare a mapping document from Souce to Destination
...

Sheet 4. Risk
A1: Risk Log | K1: Return to the Index
A3: ID | B3: Date Raised | C3: Risk Description | D3: Consequences | E3: Likelihood | F3: Impact | G3: Severity | H3: Mitigation Plan | I3: Owner | J3: Status | K3: Date Closed

Sheet 5. Assumptions
A1: Assumptions | G1: Return to the Index
A3: Sr no | B3: Date Raised | C3: Assumption Description | D3: Reason for Assumption | E3: Action to Validate | F3: Impact if Assumption Incorrect | G3: Status

Sheet 6. Issue Log
A1: Issue Log | H1: Return to the Index
A3: ID | B3: Date Raised | C3: Issue Description | D3: Impact Description | E3: Impact | F3: Priority | G3: Owner | H3: Status | I3: Resolution TAT

Sheet 7. Dependencies
A1: Dependencies | H1: Return to the Index
A3: ID | B3: Date Raised | C3: Dependency Description | D3: Owner | E3: Impact | F3: Status | G3: Due Date | H3: Remarks

Sheet 8. Meeting Notes
A1: Meeting Notes | K1: Return to the Index
A3: Sr.No | B3: Date | C3: Meeting Title | D3: Attendees | E3: Agenda | F3: Description | G3: Type | H3: Actionable by | I3: Due Date | J3: Status | K3: Conclusion / Remark

Sheet 9. Estimation
C4: Role | D4: Head Count | E4: Potential Responsibilities | F4: Effort Estimates (Man-Months)
C5: Implementation Phase
C29: Total

Sheet 10. Q&A
A1: Sr No | B1: Document Reference | C1: DocumentSection | D1: Questions | E1: Response | F1: Response Provided by | G1: Raised Date | H1: Response Received Date | I1: Remarks
A2: 1
A3: 2
A4: 3
A5: 4
A6: 5
A7: 6
A8: 7
A9: 8
A10: 9
A11: 10

Sheet HiddenWkly
A2: "Weekly" (or whatever) task view | L2: Task Not Yet Started | O2: Task is underway but is behind schedule.
L3: Task Complete | O3: Task is late and has not yet been started.
A4: start date entry | B4: =#REF! -> #REF! | L4: Task In Progress | O4: Task is scheduled for work during this timeframe.
A5: End date entry | B5: =#REF! -> #REF!
AD8: TO ORDER BY TASK OWNER | AK8: Actual list for Tab
A9: TASK NUMBER | B9: ID for Task | C9: "Rank" to list | D9: Repeat Task for VLOOKUP | E9: TASK | F9: Estimated Start Date | G9: Estimated End Date | H9: Owner | I9: Owner for List | J9: Actual Start Date | K9: Actual End Date | M9: On Track Status | N9: Task should be done - Started | O9: Task Should be done - Not Yet Started | P9: Reg Scheduled Task during this time | Q9: Sum | S9: Unique Rank for Owners, by task | T9: Owner Rank | U9: Task Owner | V9: List of tasks | W9: Task Name | X9: Est Start Date | Y9: Est End Date - DUE DATE | Z9: Completion Status | AA9: On Track Status | AD9: Possible Owner | AE9: Task Number | AF9: Yes to tasks | AG9: Unique Rank | AK9: RANK | AL9: Owner | AM9: Owner for Tab | AO9: Task | AP9: Task Status | AQ9: Due Date | AR9: Completion Status
A10: 1 | B10: =IF(OR(N10="Yes",O10="Yes",P10="Yes"),A10,"") -> #REF! | C10: =IF(B10="","",RANK(B10,$B$10:$B$109,1)) -> #REF! | D10: =IF(C10="","",E10) -> #REF! | E10: =IF(#REF!="","",#REF!) -> #REF! | F10: =IF(#REF!="","",#REF!) -> #REF! | G10: =IF(#REF!="","",#REF!) -> #REF! | H10: =IF(#REF!="","",#REF!) -> #REF! | I10: =IF(AND(H10="",NOT(E10="")),"Unassigned",H10) -> #REF! | J10: =IF(#REF!="","",#REF!) -> #REF! | K10: =IF(#REF!="","",#REF!) -> #REF! | L10: =IF(E10="","",IF(AND(J10="",K10=""),$L$2,IF(NOT(K10=""),$L$3,$L$4))) -> #REF! | M10: =IF(N10="Yes",$O$2,IF(O10="Yes",$O$3,IF(P10="Yes",$O$4,""))) -> #REF! | N10: =IF(E10="","",IF(AND(G10<=$B$4,K10="",NOT(J10="")),"Yes","No")) -> #REF! | O10: =IF(E10="","",IF(AND(G10<=$B$4,J10=""),"Yes","No")) -> #REF! | P10: =IF(OR(N10="Yes",O10="Yes"),"No",IF(AND(K10="",F10<=$B$5),"Yes","No")) -> #REF! | Q10: =SUM($A$10:A10) -> 1 | S10: =IF(T10="","",RANK(T10,$T$10:$T$50,1)+COUNTIF(T$10:T10,T10)-1) -> #REF! | T10: =IF(U10="","",VLOOKUP(U10,$AD$10:$AG$50,4,FALSE)) -> #REF! | U10: =IF(V10="","",VLOOKUP(V10,$C$10:$K$109,7,FALSE)) -> #REF! | V10: =IF(Q10<=SUM($C$10:$C$109),A10,"") -> #REF! | W10: =VLOOKUP(V10,$C$10:$K$109,2,FALSE) -> #REF! | X10: =IF($W10="","",VLOOKUP($W10,$E$10:$P$109,2,FALSE)) -> #REF! | Y10: =IF($W10="","",VLOOKUP($W10,$E$10:$P$109,3,FALSE)) -> #REF! | Z10: =IF($W10="","",VLOOKUP($W10,$E$10:$P$109,8,FALSE)) -> #REF! | AA10: =IF($W10="","",VLOOKUP($W10,$E$10:$P$109,9,FALSE)) -> #REF! | AD10: Unassigned | AE10: =IF(AD10=0,"",COUNTIF($U$10:$U$109,$AD10)) -> 0 | AF10: =IF(AE10="","",IF(AE10=0,"",AE10)) | AG10: =IF(AF10="","",RANK(AF10,$AF$10:$AF$50)+COUNTIF(AF$10:AF10,AF10)-1) | AI10: ='1. Project Details'!B16 -> 0 | AK10: 1 | AL10: =IF(SUM($S$10:$S$109)<$Q10,"",VLOOKUP($AK10,$S$10:$AA$109,3,FALSE)) -> #REF! | AM10: =IF(AL10="","",AL10) -> #REF! | AO10: =IF(SUM($S$10:$S$109)<$Q10,"",VLOOKUP(AK10,$S$10:$AA$109,5,FALSE)) -> #REF! | AP10: =IF(SUM($S$10:$S$109)<$Q10,"",VLOOKUP($AK10,$S$10:$AA$109,8,FALSE)) -> #REF! | AQ10: =IF(SUM($S$10:$S$109)<$Q10,"",VLOOKUP($AK10,$S$10:$AA$109,7,FALSE)) -> #REF! | AR10: =IF(SUM($S$10:$S$109)<$Q10,"",VLOOKUP($AK10,$S$10:$AA$109,9,FALSE)) -> #REF!
A11: 2 | B11: =IF(OR(N11="Yes",O11="Yes",P11="Yes"),A11,"") -> #REF! | C11: =IF(B11="","",RANK(B11,$B$10:$B$109,1)) -> #REF! | D11: =IF(C11="","",E11) -> #REF! | E11: =IF(#REF!="","",#REF!) -> #REF! | F11: =IF(#REF!="","",#REF!) -> #REF! | G11: =IF(#REF!="","",#REF!) -> #REF! | H11: =IF(#REF!="","",#REF!) -> #REF! | I11: =IF(AND(H11="",NOT(E11="")),"Unassigned",H11) -> #REF! | J11: =IF(#REF!="","",#REF!) -> #REF! | K11: =IF(#REF!="","",#REF!) -> #REF! | L11: =IF(E11="","",IF(AND(J11="",K11=""),$L$2,IF(NOT(K11=""),$L$3,$L$4))) -> #REF! | M11: =IF(N11="Yes",$O$2,IF(O11="Yes",$O$3,IF(P11="Yes",$O$4,""))) -> #REF! | N11: =IF(E11="","",IF(AND(G11<=$B$4,K11="",NOT(J11="")),"Yes","No")) -> #REF! | O11: =IF(E11="","",IF(AND(G11<=$B$4,J11=""),"Yes","No")) -> #REF! | P11: =IF(OR(N11="Yes",O11="Yes"),"No",IF(AND(K11="",F11<=$B$5),"Yes","No")) -> #REF! | Q11: =SUM($A$10:A11) -> 3 | S11: =IF(T11="","",RANK(T11,$T$10:$T$50,1)+COUNTIF(T$10:T11,T11)-1) -> #REF! | T11: =IF(U11="","",VLOOKUP(U11,$AD$10:$AG$50,4,FALSE)) -> #REF! | U11: =IF(V11="","",VLOOKUP(V11,$C$10:$K$109,7,FALSE)) -> #REF! | V11: =IF(Q11<=SUM($C$10:$C$109),A11,"") -> #REF! | W11: =VLOOKUP(V11,$C$10:$K$109,2,FALSE) -> #REF! | X11: =IF($W11="","",VLOOKUP($W11,$E$10:$P$109,2,FALSE)) -> #REF! | Y11: =IF($W11="","",VLOOKUP($W11,$E$10:$P$109,3,FALSE)) -> #REF! | Z11: =IF($W11="","",VLOOKUP($W11,$E$10:$P$109,8,FALSE)) -> #REF! | AA11: =IF($W11="","",VLOOKUP($W11,$E$10:$P$109,9,FALSE)) -> #REF! | AD11: ='1. Project Details'!B16 -> 0 | AE11: =IF(AD11=0,"",COUNTIF($U$10:$U$109,$AD11)) | AF11: =IF(AE11="","",IF(AE11=0,"",AE11)) | AG11: =IF(AF11="","",RANK(AF11,$AF$10:$AF$50)+COUNTIF(AF$10:AF11,AF11)-1) | AI11: ='1. Project Details'!#REF! -> #REF! | AK11: 2 | AL11: =IF(SUM($S$10:$S$109)<$Q11,"",VLOOKUP($AK11,$S$10:$AA$109,3,FALSE)) -> #REF! | AM11: =IF(AL11="","",IF(AL11=AL10,"",AL11)) -> #REF! | AO11: =IF(SUM($S$10:$S$109)<$Q11,"",VLOOKUP(AK11,$S$10:$AA$109,5,FALSE)) -> #REF! | AP11: =IF(SUM($S$10:$S$109)<$Q11,"",VLOOKUP($AK11,$S$10:$AA$109,8,FALSE)) -> #REF! | AQ11: =IF(SUM($S$10:$S$109)<$Q11,"",VLOOKUP($AK11,$S$10:$AA$109,7,FALSE)) -> #REF! | AR11: =IF(SUM($S$10:$S$109)<$Q11,"",VLOOKUP($AK11,$S$10:$AA$109,9,FALSE)) -> #REF!
A12: 3 | B12: =IF(OR(N12="Yes",O12="Yes",P12="Yes"),A12,"") -> #REF! | C12: =IF(B12="","",RANK(B12,$B$10:$B$109,1)) -> #REF! | D12: =IF(C12="","",E12) -> #REF! | E12: =IF(#REF!="","",#REF!) -> #REF! | F12: =IF(#REF!="","",#REF!) -> #REF! | G12: =IF(#REF!="","",#REF!) -> #REF! | H12: =IF(#REF!="","",#REF!) -> #REF! | I12: =IF(AND(H12="",NOT(E12="")),"Unassigned",H12) -> #REF! | J12: =IF(#REF!="","",#REF!) -> #REF! | K12: =IF(#REF!="","",#REF!) -> #REF! | L12: =IF(E12="","",IF(AND(J12="",K12=""),$L$2,IF(NOT(K12=""),$L$3,$L$4))) -> #REF! | M12: =IF(N12="Yes",$O$2,IF(O12="Yes",$O$3,IF(P12="Yes",$O$4,""))) -> #REF! | N12: =IF(E12="","",IF(AND(G12<=$B$4,K12="",NOT(J12="")),"Yes","No")) -> #REF! | O12: =IF(E12="","",IF(AND(G12<=$B$4,J12=""),"Yes","No")) -> #REF! | P12: =IF(OR(N12="Yes",O12="Yes"),"No",IF(AND(K12="",F12<=$B$5),"Yes","No")) -> #REF! | Q12: =SUM($A$10:A12) -> 6 | S12: =IF(T12="","",RANK(T12,$T$10:$T$50,1)+COUNTIF(T$10:T12,T12)-1) -> #REF! | T12: =IF(U12="","",VLOOKUP(U12,$AD$10:$AG$50,4,FALSE)) -> #REF! | U12: =IF(V12="","",VLOOKUP(V12,$C$10:$K$109,7,FALSE)) -> #REF! | V12: =IF(Q12<=SUM($C$10:$C$109),A12,"") -> #REF! | W12: =VLOOKUP(V12,$C$10:$K$109,2,FALSE) -> #REF! | X12: =IF($W12="","",VLOOKUP($W12,$E$10:$P$109,2,FALSE)) -> #REF! | Y12: =IF($W12="","",VLOOKUP($W12,$E$10:$P$109,3,FALSE)) -> #REF! | Z12: =IF($W12="","",VLOOKUP($W12,$E$10:$P$109,8,FALSE)) -> #REF! | AA12: =IF($W12="","",VLOOKUP($W12,$E$10:$P$109,9,FALSE)) -> #REF! | AD12: ='1. Project Details'!#REF! -> #REF! | AE12: =IF(AD12=0,"",COUNTIF($U$10:$U$109,$AD12)) -> #REF! | AF12: =IF(AE12="","",IF(AE12=0,"",AE12)) -> #REF! | AG12: =IF(AF12="","",RANK(AF12,$AF$10:$AF$50)+COUNTIF(AF$10:AF12,AF12)-1) -> #REF! | AI12: ='1. Project Details'!B17 -> 0 | AK12: 3 | AL12: =IF(SUM($S$10:$S$109)<$Q12,"",VLOOKUP($AK12,$S$10:$AA$109,3,FALSE)) -> #REF! | AM12: =IF(AL12="","",IF(AL12=AL11,"",AL12)) -> #REF! | AO12: =IF(SUM($S$10:$S$109)<$Q12,"",VLOOKUP(AK12,$S$10:$AA$109,5,FALSE)) -> #REF! | AP12: =IF(SUM($S$10:$S$109)<$Q12,"",VLOOKUP($AK12,$S$10:$AA$109,8,FALSE)) -> #REF! | AQ12: =IF(SUM($S$10:$S$109)<$Q12,"",VLOOKUP($AK12,$S$10:$AA$109,7,FALSE)) -> #REF! | AR12: =IF(SUM($S$10:$S$109)<$Q12,"",VLOOKUP($AK12,$S$10:$AA$109,9,FALSE)) -> #REF!
A13: 4 | B13: =IF(OR(N13="Yes",O13="Yes",P13="Yes"),A13,"") -> #REF! | C13: =IF(B13="","",RANK(B13,$B$10:$B$109,1)) -> #REF! | D13: =IF(C13="","",E13) -> #REF! | E13: =IF(#REF!="","",#REF!) -> #REF! | F13: =IF(#REF!="","",#REF!) -> #REF! | G13: =IF(#REF!="","",#REF!) -> #REF! | H13: =IF(#REF!="","",#REF!) -> #REF! | I13: =IF(AND(H13="",NOT(E13="")),"Unassigned",H13) -> #REF! | J13: =IF(#REF!="","",#REF!) -> #REF! | K13: =IF(#REF!="","",#REF!) -> #REF! | L13: =IF(E13="","",IF(AND(J13="",K13=""),$L$2,IF(NOT(K13=""),$L$3,$L$4))) -> #REF! | M13: =IF(N13="Yes",$O$2,IF(O13="Yes",$O$3,IF(P13="Yes",$O$4,""))) -> #REF! | N13: =IF(E13="","",IF(AND(G13<=$B$4,K13="",NOT(J13="")),"Yes","No")) -> #REF! | O13: =IF(E13="","",IF(AND(G13<=$B$4,J13=""),"Yes","No")) -> #REF! | P13: =IF(OR(N13="Yes",O13="Yes"),"No",IF(AND(K13="",F13<=$B$5),"Yes","No")) -> #REF! | Q13: =SUM($A$10:A13) -> 10 | S13: =IF(T13="","",RANK(T13,$T$10:$T$50,1)+COUNTIF(T$10:T13,T13)-1) -> #REF! | T13: =IF(U13="","",VLOOKUP(U13,$AD$10:$AG$50,4,FALSE)) -> #REF! | U13: =IF(V13="","",VLOOKUP(V13,$C$10:$K$109,7,FALSE)) -> #REF! | V13: =IF(Q13<=SUM($C$10:$C$109),A13,"") -> #REF! | W13: =VLOOKUP(V13,$C$10:$K$109,2,FALSE) -> #REF! | X13: =IF($W13="","",VLOOKUP($W13,$E$10:$P$109,2,FALSE)) -> #REF! | Y13: =IF($W13="","",VLOOKUP($W13,$E$10:$P$109,3,FALSE)) -> #REF! | Z13: =IF($W13="","",VLOOKUP($W13,$E$10:$P$109,8,FALSE)) -> #REF! | AA13: =IF($W13="","",VLOOKUP($W13,$E$10:$P$109,9,FALSE)) -> #REF! | AD13: ='1. Project Details'!B17 -> 0 | AE13: =IF(AD13=0,"",COUNTIF($U$10:$U$109,$AD13)) | AF13: =IF(AE13="","",IF(AE13=0,"",AE13)) | AG13: =IF(AF13="","",RANK(AF13,$AF$10:$AF$50)+COUNTIF(AF$10:AF13,AF13)-1) | AI13: ='1. Project Details'!B20 -> 0 | AK13: 4 | AL13: =IF(SUM($S$10:$S$109)<$Q13,"",VLOOKUP($AK13,$S$10:$AA$109,3,FALSE)) -> #REF! | AM13: =IF(AL13="","",IF(AL13=AL12,"",AL13)) -> #REF! | AO13: =IF(SUM($S$10:$S$109)<$Q13,"",VLOOKUP(AK13,$S$10:$AA$109,5,FALSE)) -> #REF! | AP13: =IF(SUM($S$10:$S$109)<$Q13,"",VLOOKUP($AK13,$S$10:$AA$109,8,FALSE)) -> #REF! | AQ13: =IF(SUM($S$10:$S$109)<$Q13,"",VLOOKUP($AK13,$S$10:$AA$109,7,FALSE)) -> #REF! | AR13: =IF(SUM($S$10:$S$109)<$Q13,"",VLOOKUP($AK13,$S$10:$AA$109,9,FALSE)) -> #REF!
A14: 5 | B14: =IF(OR(N14="Yes",O14="Yes",P14="Yes"),A14,"") -> #REF! | C14: =IF(B14="","",RANK(B14,$B$10:$B$109,1)) -> #REF! | D14: =IF(C14="","",E14) -> #REF! | E14: =IF(#REF!="","",#REF!) -> #REF! | F14: =IF(#REF!="","",#REF!) -> #REF! | G14: =IF(#REF!="","",#REF!) -> #REF! | H14: =IF(#REF!="","",#REF!) -> #REF! | I14: =IF(AND(H14="",NOT(E14="")),"Unassigned",H14) -> #REF! | J14: =IF(#REF!="","",#REF!) -> #REF! | K14: =IF(#REF!="","",#REF!) -> #REF! | L14: =IF(E14="","",IF(AND(J14="",K14=""),$L$2,IF(NOT(K14=""),$L$3,$L$4))) -> #REF! | M14: =IF(N14="Yes",$O$2,IF(O14="Yes",$O$3,IF(P14="Yes",$O$4,""))) -> #REF! | N14: =IF(E14="","",IF(AND(G14<=$B$4,K14="",NOT(J14="")),"Yes","No")) -> #REF! | O14: =IF(E14="","",IF(AND(G14<=$B$4,J14=""),"Yes","No")) -> #REF! | P14: =IF(OR(N14="Yes",O14="Yes"),"No",IF(AND(K14="",F14<=$B$5),"Yes","No")) -> #REF! | Q14: =SUM($A$10:A14) -> 15 | S14: =IF(T14="","",RANK(T14,$T$10:$T$50,1)+COUNTIF(T$10:T14,T14)-1) -> #REF! | T14: =IF(U14="","",VLOOKUP(U14,$AD$10:$AG$50,4,FALSE)) -> #REF! | U14: =IF(V14="","",VLOOKUP(V14,$C$10:$K$109,7,FALSE)) -> #REF! | V14: =IF(Q14<=SUM($C$10:$C$109),A14,"") -> #REF! | W14: =VLOOKUP(V14,$C$10:$K$109,2,FALSE) -> #REF! | X14: =IF($W14="","",VLOOKUP($W14,$E$10:$P$109,2,FALSE)) -> #REF! | Y14: =IF($W14="","",VLOOKUP($W14,$E$10:$P$109,3,FALSE)) -> #REF! | Z14: =IF($W14="","",VLOOKUP($W14,$E$10:$P$109,8,FALSE)) -> #REF! | AA14: =IF($W14="","",VLOOKUP($W14,$E$10:$P$109,9,FALSE)) -> #REF! | AD14: ='1. Project Details'!B20 -> 0 | AE14: =IF(AD14=0,"",COUNTIF($U$10:$U$109,$AD14)) | AF14: =IF(AE14="","",IF(AE14=0,"",AE14)) | AG14: =IF(AF14="","",RANK(AF14,$AF$10:$AF$50)+COUNTIF(AF$10:AF14,AF14)-1) | AI14: ='1. Project Details'!B21 -> 0 | AK14: 5 | AL14: =IF(SUM($S$10:$S$109)<$Q14,"",VLOOKUP($AK14,$S$10:$AA$109,3,FALSE)) -> #REF! | AM14: =IF(AL14="","",IF(AL14=AL13,"",AL14)) -> #REF! | AO14: =IF(SUM($S$10:$S$109)<$Q14,"",VLOOKUP(AK14,$S$10:$AA$109,5,FALSE)) -> #REF! | AP14: =IF(SUM($S$10:$S$109)<$Q14,"",VLOOKUP($AK14,$S$10:$AA$109,8,FALSE)) -> #REF! | AQ14: =IF(SUM($S$10:$S$109)<$Q14,"",VLOOKUP($AK14,$S$10:$AA$109,7,FALSE)) -> #REF! | AR14: =IF(SUM($S$10:$S$109)<$Q14,"",VLOOKUP($AK14,$S$10:$AA$109,9,FALSE)) -> #REF!
A15: 6 | B15: =IF(OR(N15="Yes",O15="Yes",P15="Yes"),A15,"") -> #REF! | C15: =IF(B15="","",RANK(B15,$B$10:$B$109,1)) -> #REF! | D15: =IF(C15="","",E15) -> #REF! | E15: =IF(#REF!="","",#REF!) -> #REF! | F15: =IF(#REF!="","",#REF!) -> #REF! | G15: =IF(#REF!="","",#REF!) -> #REF! | H15: =IF(#REF!="","",#REF!) -> #REF! | I15: =IF(AND(H15="",NOT(E15="")),"Unassigned",H15) -> #REF! | J15: =IF(#REF!="","",#REF!) -> #REF! | K15: =IF(#REF!="","",#REF!) -> #REF! | L15: =IF(E15="","",IF(AND(J15="",K15=""),$L$2,IF(NOT(K15=""),$L$3,$L$4))) -> #REF! | M15: =IF(N15="Yes",$O$2,IF(O15="Yes",$O$3,IF(P15="Yes",$O$4,""))) -> #REF! | N15: =IF(E15="","",IF(AND(G15<=$B$4,K15="",NOT(J15="")),"Yes","No")) -> #REF! | O15: =IF(E15="","",IF(AND(G15<=$B$4,J15=""),"Yes","No")) -> #REF! | P15: =IF(OR(N15="Yes",O15="Yes"),"No",IF(AND(K15="",F15<=$B$5),"Yes","No")) -> #REF! | Q15: =SUM($A$10:A15) -> 21 | S15: =IF(T15="","",RANK(T15,$T$10:$T$50,1)+COUNTIF(T$10:T15,T15)-1) -> #REF! | T15: =IF(U15="","",VLOOKUP(U15,$AD$10:$AG$50,4,FALSE)) -> #REF! | U15: =IF(V15="","",VLOOKUP(V15,$C$10:$K$109,7,FALSE)) -> #REF! | V15: =IF(Q15<=SUM($C$10:$C$109),A15,"") -> #REF! | W15: =VLOOKUP(V15,$C$10:$K$109,2,FALSE) -> #REF! | X15: =IF($W15="","",VLOOKUP($W15,$E$10:$P$109,2,FALSE)) -> #REF! | Y15: =IF($W15="","",VLOOKUP($W15,$E$10:$P$109,3,FALSE)) -> #REF! | Z15: =IF($W15="","",VLOOKUP($W15,$E$10:$P$109,8,FALSE)) -> #REF! | AA15: =IF($W15="","",VLOOKUP($W15,$E$10:$P$109,9,FALSE)) -> #REF! | AD15: ='1. Project Details'!B21 -> 0 | AE15: =IF(AD15=0,"",COUNTIF($U$10:$U$109,$AD15)) | AF15: =IF(AE15="","",IF(AE15=0,"",AE15)) | AG15: =IF(AF15="","",RANK(AF15,$AF$10:$AF$50)+COUNTIF(AF$10:AF15,AF15)-1) | AI15: ='1. Project Details'!B22 -> 0 | AK15: 6 | AL15: =IF(SUM($S$10:$S$109)<$Q15,"",VLOOKUP($AK15,$S$10:$AA$109,3,FALSE)) -> #REF! | AM15: =IF(AL15="","",IF(AL15=AL14,"",AL15)) -> #REF! | AO15: =IF(SUM($S$10:$S$109)<$Q15,"",VLOOKUP(AK15,$S$10:$AA$109,5,FALSE)) -> #REF! | AP15: =IF(SUM($S$10:$S$109)<$Q15,"",VLOOKUP($AK15,$S$10:$AA$109,8,FALSE)) -> #REF! | AQ15: =IF(SUM($S$10:$S$109)<$Q15,"",VLOOKUP($AK15,$S$10:$AA$109,7,FALSE)) -> #REF! | AR15: =IF(SUM($S$10:$S$109)<$Q15,"",VLOOKUP($AK15,$S$10:$AA$109,9,FALSE)) -> #REF!
A16: 7 | B16: =IF(OR(N16="Yes",O16="Yes",P16="Yes"),A16,"") -> #REF! | C16: =IF(B16="","",RANK(B16,$B$10:$B$109,1)) -> #REF! | D16: =IF(C16="","",E16) -> #REF! | E16: =IF(#REF!="","",#REF!) -> #REF! | F16: =IF(#REF!="","",#REF!) -> #REF! | G16: =IF(#REF!="","",#REF!) -> #REF! | H16: =IF(#REF!="","",#REF!) -> #REF! | I16: =IF(AND(H16="",NOT(E16="")),"Unassigned",H16) -> #REF! | J16: =IF(#REF!="","",#REF!) -> #REF! | K16: =IF(#REF!="","",#REF!) -> #REF! | L16: =IF(E16="","",IF(AND(J16="",K16=""),$L$2,IF(NOT(K16=""),$L$3,$L$4))) -> #REF! | M16: =IF(N16="Yes",$O$2,IF(O16="Yes",$O$3,IF(P16="Yes",$O$4,""))) -> #REF! | N16: =IF(E16="","",IF(AND(G16<=$B$4,K16="",NOT(J16="")),"Yes","No")) -> #REF! | O16: =IF(E16="","",IF(AND(G16<=$B$4,J16=""),"Yes","No")) -> #REF! | P16: =IF(OR(N16="Yes",O16="Yes"),"No",IF(AND(K16="",F16<=$B$5),"Yes","No")) -> #REF! | Q16: =SUM($A$10:A16) -> 28 | S16: =IF(T16="","",RANK(T16,$T$10:$T$50,1)+COUNTIF(T$10:T16,T16)-1) -> #REF! | T16: =IF(U16="","",VLOOKUP(U16,$AD$10:$AG$50,4,FALSE)) -> #REF! | U16: =IF(V16="","",VLOOKUP(V16,$C$10:$K$109,7,FALSE)) -> #REF! | V16: =IF(Q16<=SUM($C$10:$C$109),A16,"") -> #REF! | W16: =VLOOKUP(V16,$C$10:$K$109,2,FALSE) -> #REF! | X16: =IF($W16="","",VLOOKUP($W16,$E$10:$P$109,2,FALSE)) -> #REF! | Y16: =IF($W16="","",VLOOKUP($W16,$E$10:$P$109,3,FALSE)) -> #REF! | Z16: =IF($W16="","",VLOOKUP($W16,$E$10:$P$109,8,FALSE)) -> #REF! | AA16: =IF($W16="","",VLOOKUP($W16,$E$10:$P$109,9,FALSE)) -> #REF! | AD16: ='1. Project Details'!B22 -> 0 | AE16: =IF(AD16=0,"",COUNTIF($U$10:$U$109,$AD16)) | AF16: =IF(AE16="","",IF(AE16=0,"",AE16)) | AG16: =IF(AF16="","",RANK(AF16,$AF$10:$AF$50)+COUNTIF(AF$10:AF16,AF16)-1) | AI16: ='1. Project Details'!B23 -> 0 | AK16: 7 | AL16: =IF(SUM($S$10:$S$109)<$Q16,"",VLOOKUP($AK16,$S$10:$AA$109,3,FALSE)) -> #REF! | AM16: =IF(AL16="","",IF(AL16=AL15,"",AL16)) -> #REF! | AO16: =IF(SUM($S$10:$S$109)<$Q16,"",VLOOKUP(AK16,$S$10:$AA$109,5,FALSE)) -> #REF! | AP16: =IF(SUM($S$10:$S$109)<$Q16,"",VLOOKUP($AK16,$S$10:$AA$109,8,FALSE)) -> #REF! | AQ16: =IF(SUM($S$10:$S$109)<$Q16,"",VLOOKUP($AK16,$S$10:$AA$109,7,FALSE)) -> #REF! | AR16: =IF(SUM($S$10:$S$109)<$Q16,"",VLOOKUP($AK16,$S$10:$AA$109,9,FALSE)) -> #REF!
A17: 8 | B17: =IF(OR(N17="Yes",O17="Yes",P17="Yes"),A17,"") -> #REF! | C17: =IF(B17="","",RANK(B17,$B$10:$B$109,1)) -> #REF! | D17: =IF(C17="","",E17) -> #REF! | E17: =IF(#REF!="","",#REF!) -> #REF! | F17: =IF(#REF!="","",#REF!) -> #REF! | G17: =IF(#REF!="","",#REF!) -> #REF! | H17: =IF(#REF!="","",#REF!) -> #REF! | I17: =IF(AND(H17="",NOT(E17="")),"Unassigned",H17) -> #REF! | J17: =IF(#REF!="","",#REF!) -> #REF! | K17: =IF(#REF!="","",#REF!) -> #REF! | L17: =IF(E17="","",IF(AND(J17="",K17=""),$L$2,IF(NOT(K17=""),$L$3,$L$4))) -> #REF! | M17: =IF(N17="Yes",$O$2,IF(O17="Yes",$O$3,IF(P17="Yes",$O$4,""))) -> #REF! | N17: =IF(E17="","",IF(AND(G17<=$B$4,K17="",NOT(J17="")),"Yes","No")) -> #REF! | O17: =IF(E17="","",IF(AND(G17<=$B$4,J17=""),"Yes","No")) -> #REF! | P17: =IF(OR(N17="Yes",O17="Yes"),"No",IF(AND(K17="",F17<=$B$5),"Yes","No")) -> #REF! | Q17: =SUM($A$10:A17) -> 36 | S17: =IF(T17="","",RANK(T17,$T$10:$T$50,1)+COUNTIF(T$10:T17,T17)-1) -> #REF! | T17: =IF(U17="","",VLOOKUP(U17,$AD$10:$AG$50,4,FALSE)) -> #REF! | U17: =IF(V17="","",VLOOKUP(V17,$C$10:$K$109,7,FALSE)) -> #REF! | V17: =IF(Q17<=SUM($C$10:$C$109),A17,"") -> #REF! | W17: =VLOOKUP(V17,$C$10:$K$109,2,FALSE) -> #REF! | X17: =IF($W17="","",VLOOKUP($W17,$E$10:$P$109,2,FALSE)) -> #REF! | Y17: =IF($W17="","",VLOOKUP($W17,$E$10:$P$109,3,FALSE)) -> #REF! | Z17: =IF($W17="","",VLOOKUP($W17,$E$10:$P$109,8,FALSE)) -> #REF! | AA17: =IF($W17="","",VLOOKUP($W17,$E$10:$P$109,9,FALSE)) -> #REF! | AD17: ='1. Project Details'!B23 -> 0 | AE17: =IF(AD17=0,"",COUNTIF($U$10:$U$109,$AD17)) | AF17: =IF(AE17="","",IF(AE17=0,"",AE17)) | AG17: =IF(AF17="","",RANK(AF17,$AF$10:$AF$50)+COUNTIF(AF$10:AF17,AF17)-1) | AI17: ='1. Project Details'!#REF! -> #REF! | AK17: 8 | AL17: =IF(SUM($S$10:$S$109)<$Q17,"",VLOOKUP($AK17,$S$10:$AA$109,3,FALSE)) -> #REF! | AM17: =IF(AL17="","",IF(AL17=AL16,"",AL17)) -> #REF! | AO17: =IF(SUM($S$10:$S$109)<$Q17,"",VLOOKUP(AK17,$S$10:$AA$109,5,FALSE)) -> #REF! | AP17: =IF(SUM($S$10:$S$109)<$Q17,"",VLOOKUP($AK17,$S$10:$AA$109,8,FALSE)) -> #REF! | AQ17: =IF(SUM($S$10:$S$109)<$Q17,"",VLOOKUP($AK17,$S$10:$AA$109,7,FALSE)) -> #REF! | AR17: =IF(SUM($S$10:$S$109)<$Q17,"",VLOOKUP($AK17,$S$10:$AA$109,9,FALSE)) -> #REF!
A18: 9 | B18: =IF(OR(N18="Yes",O18="Yes",P18="Yes"),A18,"") -> #REF! | C18: =IF(B18="","",RANK(B18,$B$10:$B$109,1)) -> #REF! | D18: =IF(C18="","",E18) -> #REF! | E18: =IF(#REF!="","",#REF!) -> #REF! | F18: =IF(#REF!="","",#REF!) -> #REF! | G18: =IF(#REF!="","",#REF!) -> #REF! | H18: =IF(#REF!="","",#REF!) -> #REF! | I18: =IF(AND(H18="",NOT(E18="")),"Unassigned",H18) -> #REF! | J18: =IF(#REF!="","",#REF!) -> #REF! | K18: =IF(#REF!="","",#REF!) -> #REF! | L18: =IF(E18="","",IF(AND(J18="",K18=""),$L$2,IF(NOT(K18=""),$L$3,$L$4))) -> #REF! | M18: =IF(N18="Yes",$O$2,IF(O18="Yes",$O$3,IF(P18="Yes",$O$4,""))) -> #REF! | N18: =IF(E18="","",IF(AND(G18<=$B$4,K18="",NOT(J18="")),"Yes","No")) -> #REF! | O18: =IF(E18="","",IF(AND(G18<=$B$4,J18=""),"Yes","No")) -> #REF! | P18: =IF(OR(N18="Yes",O18="Yes"),"No",IF(AND(K18="",F18<=$B$5),"Yes","No")) -> #REF! | Q18: =SUM($A$10:A18) -> 45 | S18: =IF(T18="","",RANK(T18,$T$10:$T$50,1)+COUNTIF(T$10:T18,T18)-1) -> #REF! | T18: =IF(U18="","",VLOOKUP(U18,$AD$10:$AG$50,4,FALSE)) -> #REF! | U18: =IF(V18="","",VLOOKUP(V18,$C$10:$K$109,7,FALSE)) -> #REF! | V18: =IF(Q18<=SUM($C$10:$C$109),A18,"") -> #REF! | W18: =VLOOKUP(V18,$C$10:$K$109,2,FALSE) -> #REF! | X18: =IF($W18="","",VLOOKUP($W18,$E$10:$P$109,2,FALSE)) -> #REF! | Y18: =IF($W18="","",VLOOKUP($W18,$E$10:$P$109,3,FALSE)) -> #REF! | Z18: =IF($W18="","",VLOOKUP($W18,$E$10:$P$109,8,FALSE)) -> #REF! | AA18: =IF($W18="","",VLOOKUP($W18,$E$10:$P$109,9,FALSE)) -> #REF! | AD18: ='1. Project Details'!#REF! -> #REF! | AE18: =IF(AD18=0,"",COUNTIF($U$10:$U$109,$AD18)) -> #REF! | AF18: =IF(AE18="","",IF(AE18=0,"",AE18)) -> #REF! | AG18: =IF(AF18="","",RANK(AF18,$AF$10:$AF$50)+COUNTIF(AF$10:AF18,AF18)-1) -> #REF! | AI18: ='1. Project Details'!B24 -> 0 | AK18: 9 | AL18: =IF(SUM($S$10:$S$109)<$Q18,"",VLOOKUP($AK18,$S$10:$AA$109,3,FALSE)) -> #REF! | AM18: =IF(AL18="","",IF(AL18=AL17,"",AL18)) -> #REF! | AO18: =IF(SUM($S$10:$S$109)<$Q18,"",VLOOKUP(AK18,$S$10:$AA$109,5,FALSE)) -> #REF! | AP18: =IF(SUM($S$10:$S$109)<$Q18,"",VLOOKUP($AK18,$S$10:$AA$109,8,FALSE)) -> #REF! | AQ18: =IF(SUM($S$10:$S$109)<$Q18,"",VLOOKUP($AK18,$S$10:$AA$109,7,FALSE)) -> #REF! | AR18: =IF(SUM($S$10:$S$109)<$Q18,"",VLOOKUP($AK18,$S$10:$AA$109,9,FALSE)) -> #REF!
A19: 10 | B19: =IF(OR(N19="Yes",O19="Yes",P19="Yes"),A19,"") -> #REF! | C19: =IF(B19="","",RANK(B19,$B$10:$B$109,1)) -> #REF! | D19: =IF(C19="","",E19) -> #REF! | E19: =IF(#REF!="","",#REF!) -> #REF! | F19: =IF(#REF!="","",#REF!) -> #REF! | G19: =IF(#REF!="","",#REF!) -> #REF! | H19: =IF(#REF!="","",#REF!) -> #REF! | I19: =IF(AND(H19="",NOT(E19="")),"Unassigned",H19) -> #REF! | J19: =IF(#REF!="","",#REF!) -> #REF! | K19: =IF(#REF!="","",#REF!) -> #REF! | L19: =IF(E19="","",IF(AND(J19="",K19=""),$L$2,IF(NOT(K19=""),$L$3,$L$4))) -> #REF! | M19: =IF(N19="Yes",$O$2,IF(O19="Yes",$O$3,IF(P19="Yes",$O$4,""))) -> #REF! | N19: =IF(E19="","",IF(AND(G19<=$B$4,K19="",NOT(J19="")),"Yes","No")) -> #REF! | O19: =IF(E19="","",IF(AND(G19<=$B$4,J19=""),"Yes","No")) -> #REF! | P19: =IF(OR(N19="Yes",O19="Yes"),"No",IF(AND(K19="",F19<=$B$5),"Yes","No")) -> #REF! | Q19: =SUM($A$10:A19) -> 55 | S19: =IF(T19="","",RANK(T19,$T$10:$T$50,1)+COUNTIF(T$10:T19,T19)-1) -> #REF! | T19: =IF(U19="","",VLOOKUP(U19,$AD$10:$AG$50,4,FALSE)) -> #REF! | U19: =IF(V19="","",VLOOKUP(V19,$C$10:$K$109,7,FALSE)) -> #REF! | V19: =IF(Q19<=SUM($C$10:$C$109),A19,"") -> #REF! | W19: =VLOOKUP(V19,$C$10:$K$109,2,FALSE) -> #REF! | X19: =IF($W19="","",VLOOKUP($W19,$E$10:$P$109,2,FALSE)) -> #REF! | Y19: =IF($W19="","",VLOOKUP($W19,$E$10:$P$109,3,FALSE)) -> #REF! | Z19: =IF($W19="","",VLOOKUP($W19,$E$10:$P$109,8,FALSE)) -> #REF! | AA19: =IF($W19="","",VLOOKUP($W19,$E$10:$P$109,9,FALSE)) -> #REF! | AD19: ='1. Project Details'!B24 -> 0 | AE19: =IF(AD19=0,"",COUNTIF($U$10:$U$109,$AD19)) | AF19: =IF(AE19="","",IF(AE19=0,"",AE19)) | AG19: =IF(AF19="","",RANK(AF19,$AF$10:$AF$50)+COUNTIF(AF$10:AF19,AF19)-1) | AI19: ='1. Project Details'!#REF! -> #REF! | AK19: 10 | AL19: =IF(SUM($S$10:$S$109)<$Q19,"",VLOOKUP($AK19,$S$10:$AA$109,3,FALSE)) -> #REF! | AM19: =IF(AL19="","",IF(AL19=AL18,"",AL19)) -> #REF! | AO19: =IF(SUM($S$10:$S$109)<$Q19,"",VLOOKUP(AK19,$S$10:$AA$109,5,FALSE)) -> #REF! | AP19: =IF(SUM($S$10:$S$109)<$Q19,"",VLOOKUP($AK19,$S$10:$AA$109,8,FALSE)) -> #REF! | AQ19: =IF(SUM($S$10:$S$109)<$Q19,"",VLOOKUP($AK19,$S$10:$AA$109,7,FALSE)) -> #REF! | AR19: =IF(SUM($S$10:$S$109)<$Q19,"",VLOOKUP($AK19,$S$10:$AA$109,9,FALSE)) -> #REF!
A20: 11 | B20: =IF(OR(N20="Yes",O20="Yes",P20="Yes"),A20,"") -> #REF! | C20: =IF(B20="","",RANK(B20,$B$10:$B$109,1)) -> #REF! | D20: =IF(C20="","",E20) -> #REF! | E20: =IF(#REF!="","",#REF!) -> #REF! | F20: =IF(#REF!="","",#REF!) -> #REF! | G20: =IF(#REF!="","",#REF!) -> #REF! | H20: =IF(#REF!="","",#REF!) -> #REF! | I20: =IF(AND(H20="",NOT(E20="")),"Unassigned",H20) -> #REF! | J20: =IF(#REF!="","",#REF!) -> #REF! | K20: =IF(#REF!="","",#REF!) -> #REF! | L20: =IF(E20="","",IF(AND(J20="",K20=""),$L$2,IF(NOT(K20=""),$L$3,$L$4))) -> #REF! | M20: =IF(N20="Yes",$O$2,IF(O20="Yes",$O$3,IF(P20="Yes",$O$4,""))) -> #REF! | N20: =IF(E20="","",IF(AND(G20<=$B$4,K20="",NOT(J20="")),"Yes","No")) -> #REF! | O20: =IF(E20="","",IF(AND(G20<=$B$4,J20=""),"Yes","No")) -> #REF! | P20: =IF(OR(N20="Yes",O20="Yes"),"No",IF(AND(K20="",F20<=$B$5),"Yes","No")) -> #REF! | Q20: =SUM($A$10:A20) -> 66 | S20: =IF(T20="","",RANK(T20,$T$10:$T$50,1)+COUNTIF(T$10:T20,T20)-1) -> #REF! | T20: =IF(U20="","",VLOOKUP(U20,$AD$10:$AG$50,4,FALSE)) -> #REF! | U20: =IF(V20="","",VLOOKUP(V20,$C$10:$K$109,7,FALSE)) -> #REF! | V20: =IF(Q20<=SUM($C$10:$C$109),A20,"") -> #REF! | W20: =VLOOKUP(V20,$C$10:$K$109,2,FALSE) -> #REF! | X20: =IF($W20="","",VLOOKUP($W20,$E$10:$P$109,2,FALSE)) -> #REF! | Y20: =IF($W20="","",VLOOKUP($W20,$E$10:$P$109,3,FALSE)) -> #REF! | Z20: =IF($W20="","",VLOOKUP($W20,$E$10:$P$109,8,FALSE)) -> #REF! | AA20: =IF($W20="","",VLOOKUP($W20,$E$10:$P$109,9,FALSE)) -> #REF! | AD20: ='1. Project Details'!#REF! -> #REF! | AE20: =IF(AD20=0,"",COUNTIF($U$10:$U$109,$AD20)) -> #REF! | AF20: =IF(AE20="","",IF(AE20=0,"",AE20)) -> #REF! | AG20: =IF(AF20="","",RANK(AF20,$AF$10:$AF$50)+COUNTIF(AF$10:AF20,AF20)-1) -> #REF! | AI20: ='1. Project Details'!#REF! -> #REF! | AK20: 11 | AL20: =IF(SUM($S$10:$S$109)<$Q20,"",VLOOKUP($AK20,$S$10:$AA$109,3,FALSE)) -> #REF! | AM20: =IF(AL20="","",IF(AL20=AL19,"",AL20)) -> #REF! | AO20: =IF(SUM($S$10:$S$109)<$Q20,"",VLOOKUP(AK20,$S$10:$AA$109,5,FALSE)) -> #REF! | AP20: =IF(SUM($S$10:$S$109)<$Q20,"",VLOOKUP($AK20,$S$10:$AA$109,8,FALSE)) -> #REF! | AQ20: =IF(SUM($S$10:$S$109)<$Q20,"",VLOOKUP($AK20,$S$10:$AA$109,7,FALSE)) -> #REF! | AR20: =IF(SUM($S$10:$S$109)<$Q20,"",VLOOKUP($AK20,$S$10:$AA$109,9,FALSE)) -> #REF!
A21: 12 | B21: =IF(OR(N21="Yes",O21="Yes",P21="Yes"),A21,"") -> #REF! | C21: =IF(B21="","",RANK(B21,$B$10:$B$109,1)) -> #REF! | D21: =IF(C21="","",E21) -> #REF! | E21: =IF(#REF!="","",#REF!) -> #REF! | F21: =IF(#REF!="","",#REF!) -> #REF! | G21: =IF(#REF!="","",#REF!) -> #REF! | H21: =IF(#REF!="","",#REF!) -> #REF! | I21: =IF(AND(H21="",NOT(E21="")),"Unassigned",H21) -> #REF! | J21: =IF(#REF!="","",#REF!) -> #REF! | K21: =IF(#REF!="","",#REF!) -> #REF! | L21: =IF(E21="","",IF(AND(J21="",K21=""),$L$2,IF(NOT(K21=""),$L$3,$L$4))) -> #REF! | M21: =IF(N21="Yes",$O$2,IF(O21="Yes",$O$3,IF(P21="Yes",$O$4,""))) -> #REF! | N21: =IF(E21="","",IF(AND(G21<=$B$4,K21="",NOT(J21="")),"Yes","No")) -> #REF! | O21: =IF(E21="","",IF(AND(G21<=$B$4,J21=""),"Yes","No")) -> #REF! | P21: =IF(OR(N21="Yes",O21="Yes"),"No",IF(AND(K21="",F21<=$B$5),"Yes","No")) -> #REF! | Q21: =SUM($A$10:A21) -> 78 | S21: =IF(T21="","",RANK(T21,$T$10:$T$50,1)+COUNTIF(T$10:T21,T21)-1) -> #REF! | T21: =IF(U21="","",VLOOKUP(U21,$AD$10:$AG$50,4,FALSE)) -> #REF! | U21: =IF(V21="","",VLOOKUP(V21,$C$10:$K$109,7,FALSE)) -> #REF! | V21: =IF(Q21<=SUM($C$10:$C$109),A21,"") -> #REF! | W21: =VLOOKUP(V21,$C$10:$K$109,2,FALSE) -> #REF! | X21: =IF($W21="","",VLOOKUP($W21,$E$10:$P$109,2,FALSE)) -> #REF! | Y21: =IF($W21="","",VLOOKUP($W21,$E$10:$P$109,3,FALSE)) -> #REF! | Z21: =IF($W21="","",VLOOKUP($W21,$E$10:$P$109,8,FALSE)) -> #REF! | AA21: =IF($W21="","",VLOOKUP($W21,$E$10:$P$109,9,FALSE)) -> #REF! | AD21: ='1. Project Details'!#REF! -> #REF! | AE21: =IF(AD21=0,"",COUNTIF($U$10:$U$109,$AD21)) -> #REF! | AF21: =IF(AE21="","",IF(AE21=0,"",AE21)) -> #REF! | AG21: =IF(AF21="","",RANK(AF21,$AF$10:$AF$50)+COUNTIF(AF$10:AF21,AF21)-1) -> #REF! | AI21: ='1. Project Details'!#REF! -> #REF! | AK21: 12 | AL21: =IF(SUM($S$10:$S$109)<$Q21,"",VLOOKUP($AK21,$S$10:$AA$109,3,FALSE)) -> #REF! | AM21: =IF(AL21="","",IF(AL21=AL20,"",AL21)) -> #REF! | AO21: =IF(SUM($S$10:$S$109)<$Q21,"",VLOOKUP(AK21,$S$10:$AA$109,5,FALSE)) -> #REF! | AP21: =IF(SUM($S$10:$S$109)<$Q21,"",VLOOKUP($AK21,$S$10:$AA$109,8,FALSE)) -> #REF! | AQ21: =IF(SUM($S$10:$S$109)<$Q21,"",VLOOKUP($AK21,$S$10:$AA$109,7,FALSE)) -> #REF! | AR21: =IF(SUM($S$10:$S$109)<$Q21,"",VLOOKUP($AK21,$S$10:$AA$109,9,FALSE)) -> #REF!
A22: 13 | B22: =IF(OR(N22="Yes",O22="Yes",P22="Yes"),A22,"") -> #REF! | C22: =IF(B22="","",RANK(B22,$B$10:$B$109,1)) -> #REF! | D22: =IF(C22="","",E22) -> #REF! | E22: =IF(#REF!="","",#REF!) -> #REF! | F22: =IF(#REF!="","",#REF!) -> #REF! | G22: =IF(#REF!="","",#REF!) -> #REF! | H22: =IF(#REF!="","",#REF!) -> #REF! | I22: =IF(AND(H22="",NOT(E22="")),"Unassigned",H22) -> #REF! | J22: =IF(#REF!="","",#REF!) -> #REF! | K22: =IF(#REF!="","",#REF!) -> #REF! | L22: =IF(E22="","",IF(AND(J22="",K22=""),$L$2,IF(NOT(K22=""),$L$3,$L$4))) -> #REF! | M22: =IF(N22="Yes",$O$2,IF(O22="Yes",$O$3,IF(P22="Yes",$O$4,""))) -> #REF! | N22: =IF(E22="","",IF(AND(G22<=$B$4,K22="",NOT(J22="")),"Yes","No")) -> #REF! | O22: =IF(E22="","",IF(AND(G22<=$B$4,J22=""),"Yes","No")) -> #REF! | P22: =IF(OR(N22="Yes",O22="Yes"),"No",IF(AND(K22="",F22<=$B$5),"Yes","No")) -> #REF! | Q22: =SUM($A$10:A22) -> 91 | S22: =IF(T22="","",RANK(T22,$T$10:$T$50,1)+COUNTIF(T$10:T22,T22)-1) -> #REF! | T22: =IF(U22="","",VLOOKUP(U22,$AD$10:$AG$50,4,FALSE)) -> #REF! | U22: =IF(V22="","",VLOOKUP(V22,$C$10:$K$109,7,FALSE)) -> #REF! | V22: =IF(Q22<=SUM($C$10:$C$109),A22,"") -> #REF! | W22: =VLOOKUP(V22,$C$10:$K$109,2,FALSE) -> #REF! | X22: =IF($W22="","",VLOOKUP($W22,$E$10:$P$109,2,FALSE)) -> #REF! | Y22: =IF($W22="","",VLOOKUP($W22,$E$10:$P$109,3,FALSE)) -> #REF! | Z22: =IF($W22="","",VLOOKUP($W22,$E$10:$P$109,8,FALSE)) -> #REF! | AA22: =IF($W22="","",VLOOKUP($W22,$E$10:$P$109,9,FALSE)) -> #REF! | AD22: ='1. Project Details'!#REF! -> #REF! | AE22: =IF(AD22=0,"",COUNTIF($U$10:$U$109,$AD22)) -> #REF! | AF22: =IF(AE22="","",IF(AE22=0,"",AE22)) -> #REF! | AG22: =IF(AF22="","",RANK(AF22,$AF$10:$AF$50)+COUNTIF(AF$10:AF22,AF22)-1) -> #REF! | AI22: ='1. Project Details'!#REF! -> #REF! | AK22: 13 | AL22: =IF(SUM($S$10:$S$109)<$Q22,"",VLOOKUP($AK22,$S$10:$AA$109,3,FALSE)) -> #REF! | AM22: =IF(AL22="","",IF(AL22=AL21,"",AL22)) -> #REF! | AO22: =IF(SUM($S$10:$S$109)<$Q22,"",VLOOKUP(AK22,$S$10:$AA$109,5,FALSE)) -> #REF! | AP22: =IF(SUM($S$10:$S$109)<$Q22,"",VLOOKUP($AK22,$S$10:$AA$109,8,FALSE)) -> #REF! | AQ22: =IF(SUM($S$10:$S$109)<$Q22,"",VLOOKUP($AK22,$S$10:$AA$109,7,FALSE)) -> #REF! | AR22: =IF(SUM($S$10:$S$109)<$Q22,"",VLOOKUP($AK22,$S$10:$AA$109,9,FALSE)) -> #REF!
